Workbook

Sheet 対応表
A1: { | B1: okemoji | C1: japanese | D1: 備考/用例 | E1: URL① | F1: ② | G1: ③ | H1: ④ | I1: ⑤ | J1: ⑥
B2: ァ | C2: 0
B3: ア | C3: 1
B4: ィ | C4: 2
B5: イ | C5: 3
B6: ゥ | C6: 4
B7: ウ | C7: 5
B8: ェ | C8: 6
B9: エ | C9: 7
B10: ォ | C10: 8
B11: オ | C11: 9
B12: カ | C12: 10
B13: ガ | C13: 11
... B71: ユ | C71: 69
B72: 东 | C72: あ
B73: 代 | C73: い
B74: 乱 | C74: う
B75: 仃 | C75: え
B76: 僌 | C76: お
B77: 丌 | C77: か
B78: 丄 | C78: き
B79: 乇 | C79: く
B80: 丟 | C80: け
B81: 一 | C81: こ
B82: 乡 | C82: さ
B83: 丣 | C83: し
... B134: 刬 | C134: べ
B135: 丽 | C135: ぼ | D135: おぼろ区 | E135: おぼろ区
B136: 傫 | C136: ぱ
B137: 凋 | C137: ぴ
B138: 傰 | C138: ぷ
B139: 倨 | C139: ぺ
B140: 俊 | C140: ぽ
B141: 侔 | C141: ぇ
B142: 俬 | C142: ゃ
B143: 伖 | C143: ゅ
B144: 亞 | C144: ょ
B145: 仝 | C145: っ
B146: 傯 | C146: ー
B147: 乵 | C147: 日
...

Sheet unicode
B1: ァ | D1: ア | F1: ィ | H1: イ | J1: ゥ | L1: ウ | N1: ェ | P1: エ | R1: ォ | T1: オ | V1: カ | X1: ガ | Z1: キ | AB1: ギ | AD1: ク | AF1: グ | AH1: ケ | AJ1: ゲ | AL1: コ | AN1: ゴ | AP1: サ | AR1: ザ | AT1: シ | AV1: ジ | AX1: ス | AZ1: ズ | BB1: セ | BD1: ゼ | BF1: ソ | BH1: ゾ | BJ1: タ | BL1: ダ | BN1: チ | BP1: ヂ | BR1: ッ | BT1: ツ | BV1: ヅ | BX1: テ | BZ1: デ | CB1: ト | CD1: ド | CF1: ナ | CH1: ニ | CJ1: ヌ | CL1: ネ | CN1: ノ | CP1: ハ | CR1: バ | CT1: パ | CV1: ヒ | CX1: ビ | CZ1: ピ | DB1: フ | DD1: ブ | DF1: プ | DH1: ヘ | DJ1: ベ | DL1: ペ | DN1: ホ | DP1: ボ | DR1: ポ | DT1: マ | DV1: ミ | DX1: ム | DZ1: メ | EB1: モ | ED1: ャ | EF1: ヤ | EH1: ュ | EJ1: ユ
A2: 〇 | B2: 0 | D2: 1 | F2: 2 | H2: 3 | J2: 4 | L2: 5 | N2: 6 | P2: 7 | R2: 8 | T2: 9 | V2: 10 | X2: 11 | Z2: 12 | AB2: 13 | AD2: 14 | AF2: 15 | AH2: 16 | AJ2: 17 | AL2: 18 | AN2: 19 | AP2: 20 | AR2: 21 | AT2: 22 | AV2: 23 | AX2: 24 | AZ2: 25 | BB2: 26 | BD2: 27 | BF2: 28 | BH2: 29 | BJ2: 30 | BL2: 31 | BN2: 32 | BP2: 33 | BR2: 34 | BT2: 35 | BV2: 36 | BX2: 37 | BZ2: 38 | CB2: 39 | CD2: 40 | CF2: 41 | CH2: 42 | CJ2: 43 | CL2: 44 | CN2: 45 | CP2: 46 | CR2: 47 | CT2: 48 | CV2: 49 | CX2: 50 | CZ2: 51 | DB2: 52 | DD2: 53 | DF2: 54 | DH2: 55 | DJ2: 56 | DL2: 57 | DN2: 58 | DP2: 59 | DR2: 60 | DT2: 61 | DV2: 62 | DX2: 63 | DZ2: 64 | EB2: 65 | ED2: 66 | EF2: 67 | EH2: 68 | EJ2: 69
A3: Ａ | B3: 一 | C3: =_xlfn.XLOOKUP(B3,対応表!$B:$B,対応表!$C:$C," ") -> こ | D3: 且 | E3: =_xlfn.XLOOKUP(D3,対応表!$B:$B,対応表!$C:$C," ") -> び | F3: 丨 | G3: =_xlfn.XLOOKUP(F3,対応表!$B:$B,対応表!$C:$C,"。") -> 。 | H3: 丼 | I3: =_xlfn.XLOOKUP(H3,対応表!$B:$B,対応表!$C:$C,"が") -> が | J3: 乐 | K3: =_xlfn.XLOOKUP(J3,対応表!$B:$B,対応表!$C:$C," ") -> せ | L3: 乤 | M3: く | N3: 乸 | O3: =_xlfn.XLOOKUP(N3,対応表!$B:$B,対応表!$C:$C," ") -> 営 | P3: 二 | Q3: =_xlfn.XLOOKUP(P3,対応表!$B:$B,対応表!$C:$C," ") | R3: 亠 | S3: =_xlfn.XLOOKUP(R3,対応表!$B:$B,対応表!$C:$C," ") -> ど | T3: 亴 | U3: =_xlfn.XLOOKUP(T3,対応表!$B:$B,対応表!$C:$C," ") | V3: 仈 | W3: =_xlfn.XLOOKUP(V3,対応表!$B:$B,対応表!$C:$C," ") | X3: 仜 | Y3: =_xlfn.XLOOKUP(X3,対応表!$B:$B,対応表!$C:$C," ") | Z3: 仰 | AA3: =_xlfn.XLOOKUP(Z3,対応表!$B:$B,対応表!$C:$C," ") -> 身 | AB3: 伄 | AC3: =_xlfn.XLOOKUP(AB3,対応表!$B:$B,対応表!$C:$C," ") | AD3: 优 | AE3: =_xlfn.XLOOKUP(AD3,対応表!$B:$B,対応表!$C:$C," ") | AF3: 伬 | AG3: =_xlfn.XLOOKUP(AF3,対応表!$B:$B,対応表!$C:$C," ") | AH3: 佀 | AI3: =_xlfn.XLOOKUP(AH3,対応表!$B:$B,対応表!$C:$C," ") | AJ3: 佔 | AK3: =_xlfn.XLOOKUP(AJ3,対応表!$B:$B,対応表!$C:$C," ") | AL3: 佨 | AM3: =_xlfn.XLOOKUP(AL3,対応表!$B:$B,対応表!$C:$C," ") | AN3: 佼 | AO3: =_xlfn.XLOOKUP(AN3,対応表!$B:$B,対応表!$C:$C," ") | AP3: 侐 | AQ3: =_xlfn.XLOOKUP(AP3,対応表!$B:$B,対応表!$C:$C," ") | AR3: 侤 | AS3: =_xlfn.XLOOKUP(AR3,対応表!$B:$B,対応表!$C:$C," ") -> 内 | AT3: 侸 | AU3: =_xlfn.XLOOKUP(AT3,対応表!$B:$B,対応表!$C:$C," ") -> [侸]? | AV3: 俌 | AW3: =_xlfn.XLOOKUP(AV3,対応表!$B:$B,対応表!$C:$C," ") | AX3: 俠 | AY3: =_xlfn.XLOOKUP(AX3,対応表!$B:$B,対応表!$C:$C," ") | AZ3: 俴 | BA3: =_xlfn.XLOOKUP(AZ3,対応表!$B:$B,対応表!$C:$C," ") | BB3: 倈 | BC3: =_xlfn.XLOOKUP(BB3,対応表!$B:$B,対応表!$C:$C," ") -> む | BD3: 倜 | BE3: =_xlfn.XLOOKUP(BD3,対応表!$B:$B,対応表!$C:$C," ") | BF3: 倰 | BG3: =_xlfn.XLOOKUP(BF3,対応表!$B:$B,対応表!$C:$C," ") | BH3: 偄 | BI3: =_xlfn.XLOOKUP(BH3,対応表!$B:$B,対応表!$C:$C," ") -> 明 | BJ3: 偘 | BK3: =_xlfn.XLOOKUP(BJ3,対応表!$B:$B,対応表!$C:$C," ") | BL3: 偬 | BM3: =_xlfn.XLOOKUP(BL3,対応表!$B:$B,対応表!$C:$C," ") -> 価 | BN3: 傀 | BO3: =_xlfn.XLOOKUP(BN3,対応表!$B:$B,対応表!$C:$C," ") | BP3: 傔 | BQ3: =_xlfn.XLOOKUP(BP3,対応表!$B:$B,対応表!$C:$C," ") | BR3: 储 | BS3: =_xlfn.XLOOKUP(BR3,対応表!$B:$B,対応表!$C:$C," ") | BT3: 傼 | BU3: =_xlfn.XLOOKUP(BT3,対応表!$B:$B,対応表!$C:$C," ") | BV3: 僐 | BW3: =_xlfn.XLOOKUP(BV3,対応表!$B:$B,対応表!$C:$C," ") | BX3: 僤 | BY3: =_xlfn.XLOOKUP(BX3,対応表!$B:$B,対応表!$C:$C," ") -> 寄? | BZ3: 僸 | CA3: =_xlfn.XLOOKUP(BZ3,対応表!$B:$B,対応表!$C:$C," ") | CB3: 儌 | CC3: =_xlfn.XLOOKUP(CB3,対応表!$B:$B,対応表!$C:$C," ") -> 祭 | CD3: 儠 | CE3: =_xlfn.XLOOKUP(CD3,対応表!$B:$B,対応表!$C:$C," ") | CF3: 儴 | CG3: =_xlfn.XLOOKUP(CF3,対応表!$B:$B,対応表!$C:$C," ") | CH3: 先 | CI3: =_xlfn.XLOOKUP(CH3,対応表!$B:$B,対応表!$C:$C," ") | CJ3: 兜 | CK3: =_xlfn.XLOOKUP(CJ3,対応表!$B:$B,対応表!$C:$C," ") | CL3: 兰 | CM3: =_xlfn.XLOOKUP(CL3,対応表!$B:$B,対応表!$C:$C," ") -> わ | CN3: 冄 | CO3: =_xlfn.XLOOKUP(CN3,対応表!$B:$B,対応表!$C:$C," ") | CP3: 冘 | CQ3: =_xlfn.XLOOKUP(CP3,対応表!$B:$B,対応表!$C:$C," ") | CR3: 冬 | CS3: =_xlfn.XLOOKUP(CR3,対応表!$B:$B,対応表!$C:$C," ") | CT3: 净 | CU3: =_xlfn.XLOOKUP(CT3,対応表!$B:$B,対応表!$C:$C," ") | CV3: 凔 | CW3: =_xlfn.XLOOKUP(CV3,対応表!$B:$B,対応表!$C:$C," ") | CX3: 凨 | CY3: =_xlfn.XLOOKUP(CX3,対応表!$B:$B,対応表!$C:$C," ") | CZ3: 凼 | DA3: =_xlfn.XLOOKUP(CZ3,対応表!$B:$B,対応表!$C:$C," ") | DB3: 刐 | DC3: =_xlfn.XLOOKUP(DB3,対応表!$B:$B,対応表!$C:$C," ") | DD3: 判 | DE3: =_xlfn.XLOOKUP(DD3,対応表!$B:$B,対応表!$C:$C," ") | DF3: 券 | DG3: =_xlfn.XLOOKUP(DF3,対応表!$B:$B,対応表!$C:$C," ") | DH3: 剌 | DI3: =_xlfn.XLOOKUP(DH3,対応表!$B:$B,対応表!$C:$C," ") | DJ3: 剠 | DK3: =_xlfn.XLOOKUP(DJ3,対応表!$B:$B,対応表!$C:$C," ") -> 決? | DL3: 剴 | DM3: =_xlfn.XLOOKUP(DL3,対応表!$B:$B,対応表!$C:$C," ") | DN3: 劈 | DO3: =_xlfn.XLOOKUP(DN3,対応表!$B:$B,対応表!$C:$C," ") -> 情? | DP3: 劜 | DQ3: =_xlfn.XLOOKUP(DP3,対応表!$B:$B,対応表!$C:$C," ") | DR3: 劰 | DS3: =_xlfn.XLOOKUP(DR3,対応表!$B:$B,対応表!$C:$C," ") | DT3: 勄 | DU3: =_xlfn.XLOOKUP(DT3,対応表!$B:$B,対応表!$C:$C," ") | DV3: 勘 | DW3: =_xlfn.XLOOKUP(DV3,対応表!$B:$B,対応表!$C:$C," ") | DX3: 勬 | DY3: =_xlfn.XLOOKUP(DX3,対応表!$B:$B,対応表!$C:$C," ") | DZ3: 匀 | EA3: =_xlfn.XLOOKUP(DZ3,対応表!$B:$B,対応表!$C:$C," ") | EB3: 匔 | EC3: =_xlfn.XLOOKUP(EB3,対応表!$B:$B,対応表!$C:$C," ") | ED3: 匨 | EE3: =_xlfn.XLOOKUP(ED3,対応表!$B:$B,対応表!$C:$C," ") | EF3: 匼 | EG3: =_xlfn.XLOOKUP(EF3,対応表!$B:$B,対応表!$C:$C," ") | EH3: 卐 | EI3: =_xlfn.XLOOKUP(EH3,対応表!$B:$B,対応表!$C:$C," ") | EJ3: 卤 | EK3: =_xlfn.XLOOKUP(EJ3,対応表!$B:$B,対応表!$C:$C," ")
A4: Ｂ | B4: 丁 | C4: =_xlfn.XLOOKUP(B4,対応表!$B:$B,対応表!$C:$C,"こ") -> こ | D4: 丕 | E4: {=_xlfn.XLOOKUP(D4,対応表!$B:B,対応表!$C:C," ")} -> る | F4: 丩 | G4: =_xlfn.XLOOKUP(F4,対応表!$B:$B,対応表!$C:$C," ") -> 第 | H4: 丽 | I4: =_xlfn.XLOOKUP(H4,対応表!$B:$B,対応表!$C:$C," ") -> ぼ | J4: 乑 | K4: =_xlfn.XLOOKUP(J4,対応表!$B:$B,対応表!$C:$C," ") | L4: 乥 | M4: =_xlfn.XLOOKUP(L4,対応表!$B:$B,対応表!$C:$C," ") -> ば | N4: 乹 | O4: =_xlfn.XLOOKUP(N4,対応表!$B:$B,対応表!$C:$C," ") -> み | P4: 亍 | Q4: =_xlfn.XLOOKUP(P4,対応表!$B:$B,対応表!$C:$C," ") | R4: 亡 | S4: =_xlfn.XLOOKUP(R4,対応表!$B:$B,対応表!$C:$C," ") -> 満 | T4: 亵 | U4: =_xlfn.XLOOKUP(T4,対応表!$B:$B,対応表!$C:$C," ") -> 斬? | V4: 仉 | W4: =_xlfn.XLOOKUP(V4,対応表!$B:$B,対応表!$C:$C," ") | X4: 仝 | Y4: =_xlfn.XLOOKUP(X4,対応表!$B:$B,対応表!$C:$C," ") -> っ | Z4: 仱 | AA4: =_xlfn.XLOOKUP(Z4,対応表!$B:$B,対応表!$C:$C,"に") -> に | AB4: 伅 | AC4: =_xlfn.XLOOKUP(AB4,対応表!$B:$B,対応表!$C:$C," ") -> 心 | AD4: 伙 | AE4: =_xlfn.XLOOKUP(AD4,対応表!$B:$B,対応表!$C:$C," ") | AF4: 伭 | AG4: =_xlfn.XLOOKUP(AF4,対応表!$B:$B,対応表!$C:$C," ") -> [伭]? | AH4: 佁 | AI4: =_xlfn.XLOOKUP(AH4,対応表!$B:$B,対応表!$C:$C," ") -> [佁]? | AJ4: 何 | AK4: =_xlfn.XLOOKUP(AJ4,対応表!$B:$B,対応表!$C:$C," ") | AL4: 佩 | AM4: =_xlfn.XLOOKUP(AL4,対応表!$B:$B,対応表!$C:$C," ") | AN4: 佽 | AO4: =_xlfn.XLOOKUP(AN4,対応表!$B:$B,対応表!$C:$C," ") | AP4: 侑 | AQ4: =_xlfn.XLOOKUP(AP4,対応表!$B:$B,対応表!$C:$C," ") | AR4: 侥 | AS4: =_xlfn.XLOOKUP(AR4,対応表!$B:$B,対応表!$C:$C,"に") -> に | AT4: 侹 | AU4: =_xlfn.XLOOKUP(AT4,対応表!$B:$B,対応表!$C:$C," ") | AV4: 俍 | AW4: =_xlfn.XLOOKUP(AV4,対応表!$B:$B,対応表!$C:$C," ") | AX4: 信 | AY4: =_xlfn.XLOOKUP(AX4,対応表!$B:$B,対応表!$C:$C," ") | AZ4: 俵 | BA4: =_xlfn.XLOOKUP(AZ4,対応表!$B:$B,対応表!$C:$C," ") | BB4: 倉 | BC4: =_xlfn.XLOOKUP(BB4,対応表!$B:$B,対応表!$C:$C," ") | BD4: 倝 | BE4: =_xlfn.XLOOKUP(BD4,対応表!$B:$B,対応表!$C:$C," ") | BF4: 倱 | BG4: =_xlfn.XLOOKUP(BF4,対応表!$B:$B,対応表!$C:$C," ") | BH4: 偅 | BI4: =_xlfn.XLOOKUP(BH4,対応表!$B:$B,対応表!$C:$C," ") | BJ4: 偙 | BK4: =_xlfn.XLOOKUP(BJ4,対応表!$B:$B,対応表!$C:$C," ") | BL4: 偭 | BM4: =_xlfn.XLOOKUP(BL4,対応表!$B:$B,対応表!$C:$C," ") | BN4: 傁 | BO4: =_xlfn.XLOOKUP(BN4,対応表!$B:$B,対応表!$C:$C," ") | BP4: 傕 | BQ4: =_xlfn.XLOOKUP(BP4,対応表!$B:$B,対応表!$C:$C," ") | BR4: 傩 | BS4: =_xlfn.XLOOKUP(BR4,対応表!$B:$B,対応表!$C:$C," ") | BT4: 傽 | BU4: =_xlfn.XLOOKUP(BT4,対応表!$B:$B,対応表!$C:$C," ") | BV4: 僑 | BW4: =_xlfn.XLOOKUP(BV4,対応表!$B:$B,対応表!$C:$C," ") | BX4: 僥 | BY4: =_xlfn.XLOOKUP(BX4,対応表!$B:$B,対応表!$C:$C," ") | BZ4: 價 | CA4: =_xlfn.XLOOKUP(BZ4,対応表!$B:$B,対応表!$C:$C," ") | CB4: 儍 | CC4: =_xlfn.XLOOKUP(CB4,対応表!$B:$B,対応表!$C:$C," ") | CD4: 儡 | CE4: =_xlfn.XLOOKUP(CD4,対応表!$B:$B,対応表!$C:$C," ") | CF4: 儵 | CG4: =_xlfn.XLOOKUP(CF4,対応表!$B:$B,対応表!$C:$C," ") -> 屋 | CH4: 光 | CI4: =_xlfn.XLOOKUP(CH4,対応表!$B:$B,対応表!$C:$C," ") | CJ4: 兝 | CK4: =_xlfn.XLOOKUP(CJ4,対応表!$B:$B,対応表!$C:$C," ") | CL4: 共 | CM4: =_xlfn.XLOOKUP(CL4,対応表!$B:$B,対応表!$C:$C," ") | CN4: 内 | CO4: =_xlfn.XLOOKUP(CN4,対応表!$B:$B,対応表!$C:$C," ") | CP4: 写 | CQ4: =_xlfn.XLOOKUP(CP4,対応表!$B:$B,対応表!$C:$C," ") | CR4: 冭 | CS4: =_xlfn.XLOOKUP(CR4,対応表!$B:$B,対応表!$C:$C," ") | CT4: 凁 | CU4: =_xlfn.XLOOKUP(CT4,対応表!$B:$B,対応表!$C:$C," ") | CV4: 凕 | CW4: =_xlfn.XLOOKUP(CV4,対応表!$B:$B,対応表!$C:$C," ") | CX4: 凩 | CY4: =_xlfn.XLOOKUP(CX4,対応表!$B:$B,対応表!$C:$C," ") | CZ4: 函 | DA4: =_xlfn.XLOOKUP(CZ4,対応表!$B:$B,対応表!$C:$C," ") | DB4: 刑 | DC4: =_xlfn.XLOOKUP(DB4,対応表!$B:$B,対応表!$C:$C," ") | DD4: 別 | DE4: =_xlfn.XLOOKUP(DD4,対応表!$B:$B,対応表!$C:$C," ") -> 避? | DF4: 刹 | DG4: =_xlfn.XLOOKUP(DF4,対応表!$B:$B,対応表!$C:$C," ") | DH4: 前 | DI4: =_xlfn.XLOOKUP(DH4,対応表!$B:$B,対応表!$C:$C," ") | DJ4: 剡 | DK4: =_xlfn.XLOOKUP(DJ4,対応表!$B:$B,対応表!$C:$C," ") | DL4: 創 | DM4: =_xlfn.XLOOKUP(DL4,対応表!$B:$B,対応表!$C:$C," ") -> 際? | DN4: 劉 | DO4: =_xlfn.XLOOKUP(DN4,対応表!$B:$B,対応表!$C:$C," ") -> 報? | DP4: 劝 | DQ4: =_xlfn.XLOOKUP(DP4,対応表!$B:$B,対応表!$C:$C," ") | DR4: 励 | DS4: =_xlfn.XLOOKUP(DR4,対応表!$B:$B,対応表!$C:$C," ") | DT4: 勅 | DU4: =_xlfn.XLOOKUP(DT4,対応表!$B:$B,対応表!$C:$C," ") | DV4: 務 | DW4: =_xlfn.XLOOKUP(DV4,対応表!$B:$B,対応表!$C:$C," ") | DX4: 勭 | DY4: =_xlfn.XLOOKUP(DX4,対応表!$B:$B,対応表!$C:$C," ") | DZ4: 匁 | EA4: =_xlfn.XLOOKUP(DZ4,対応表!$B:$B,対応表!$C:$C," ") | EB4: 匕 | EC4: =_xlfn.XLOOKUP(EB4,対応表!$B:$B,対応表!$C:$C," ") | ED4: 匩 | EE4: =_xlfn.XLOOKUP(ED4,対応表!$B:$B,対応表!$C:$C," ") | EF4: 匽 | EG4: =_xlfn.XLOOKUP(EF4,対応表!$B:$B,対応表!$C:$C," ") | EH4: 卑 | EI4: =_xlfn.XLOOKUP(EH4,対応表!$B:$B,対応表!$C:$C," ") | EJ4: 卥 | EK4: =_xlfn.XLOOKUP(EJ4,対応表!$B:$B,対応表!$C:$C," ")
A5: Ｃ | B5: 丂 | C5: =_xlfn.XLOOKUP(B5,対応表!$B:$B,対応表!$C:$C," ") -> に | D5: 世 | E5: {=_xlfn.XLOOKUP(D5,対応表!$B:B,対応表!$C:C," ")} -> た | F5: 个 | G5: =_xlfn.XLOOKUP(F5,対応表!$B:$B,対応表!$C:$C," ") -> 一 | H5: 举 | I5: =_xlfn.XLOOKUP(H5,対応表!$B:$B,対応表!$C:$C," ") -> や | J5: 乒 | K5: =_xlfn.XLOOKUP(J5,対応表!$B:$B,対応表!$C:$C," ") | L5: 书 | M5: =_xlfn.XLOOKUP(L5,対応表!$B:$B,対応表!$C:$C," ") -> 未? | N5: 乺 | O5: =_xlfn.XLOOKUP(N5,対応表!$B:$B,対応表!$C:$C,"に") -> に | P5: 于 | Q5: =_xlfn.XLOOKUP(P5,対応表!$B:$B,対応表!$C:$C," ") | R5: 亢 | S5: =_xlfn.XLOOKUP(R5,対応表!$B:$B,対応表!$C:$C," ") | T5: 亶 | U5: =_xlfn.XLOOKUP(T5,対応表!$B:$B,対応表!$C:$C," ") | V5: 今 | W5: =_xlfn.XLOOKUP(V5,対応表!$B:$B,対応表!$C:$C," ") | X5: 仞 | Y5: =_xlfn.XLOOKUP(X5,対応表!$B:$B,対応表!$C:$C," ") | Z5: 仲 | AA5: =_xlfn.XLOOKUP(Z5,対応表!$B:$B,対応表!$C:$C," ") -> 着 | AB5: 伆 | AC5: =_xlfn.XLOOKUP(AB5,対応表!$B:$B,対応表!$C:$C," ") | AD5: 会 | AE5: =_xlfn.XLOOKUP(AD5,対応表!$B:$B,対応表!$C:$C," ") | AF5: 伮 | AG5: =_xlfn.XLOOKUP(AF5,対応表!$B:$B,対応表!$C:$C," ") | AH5: 佂 | AI5: =_xlfn.XLOOKUP(AH5,対応表!$B:$B,対応表!$C:$C," ") | AJ5: 佖 | AK5: =_xlfn.XLOOKUP(AJ5,対応表!$B:$B,対応表!$C:$C," ") | AL5: 佪 | AM5: =_xlfn.XLOOKUP(AL5,対応表!$B:$B,対応表!$C:$C," ") | AN5: 佾 | AO5: =_xlfn.XLOOKUP(AN5,対応表!$B:$B,対応表!$C:$C," ") | AP5: 侒 | AQ5: =_xlfn.XLOOKUP(AP5,対応表!$B:$B,対応表!$C:$C," ") | AR5: 侦 | AS5: =_xlfn.XLOOKUP(AR5,対応表!$B:$B,対応表!$C:$C," ") -> 待 | AT5: 侺 | AU5: =_xlfn.XLOOKUP(AT5,対応表!$B:$B,対応表!$C:$C," ") | AV5: 俎 | AW5: =_xlfn.XLOOKUP(AV5,対応表!$B:$B,対応表!$C:$C," ") | AX5: 俢 | AY5: =_xlfn.XLOOKUP(AX5,対応表!$B:$B,対応表!$C:$C," ") | AZ5: 俶 | BA5: =_xlfn.XLOOKUP(AZ5,対応表!$B:$B,対応表!$C:$C," ") | BB5: 倊 | BC5: =_xlfn.XLOOKUP(BB5,対応表!$B:$B,対応表!$C:$C," ") | BD5: 倞 | BE5: =_xlfn.XLOOKUP(BD5,対応表!$B:$B,対応表!$C:$C," ") | BF5: 倲 | BG5: =_xlfn.XLOOKUP(BF5,対応表!$B:$B,対応表!$C:$C," ") | BH5: 偆 | BI5: =_xlfn.XLOOKUP(BH5,対応表!$B:$B,対応表!$C:$C," ") | BJ5: 做 | BK5: =_xlfn.XLOOKUP(BJ5,対応表!$B:$B,対応表!$C:$C," ") | BL5: 偮 | BM5: =_xlfn.XLOOKUP(BL5,対応表!$B:$B,対応表!$C:$C," ") -> 求? | BN5: 傂 | BO5: =_xlfn.XLOOKUP(BN5,対応表!$B:$B,対応表!$C:$C," ") | BP5: 傖 | BQ5: =_xlfn.XLOOKUP(BP5,対応表!$B:$B,対応表!$C:$C," ") | BR5: 傪 | BS5: =_xlfn.XLOOKUP(BR5,対応表!$B:$B,対応表!$C:$C," ") | BT5: 傾 | BU5: =_xlfn.XLOOKUP(BT5,対応表!$B:$B,対応表!$C:$C," ") | BV5: 僒 | BW5: =_xlfn.XLOOKUP(BV5,対応表!$B:$B,対応表!$C:$C," ") | BX5: 僦 | BY5: =_xlfn.XLOOKUP(BX5,対応表!$B:$B,対応表!$C:$C," ") | BZ5: 僺 | CA5: =_xlfn.XLOOKUP(BZ5,対応表!$B:$B,対応表!$C:$C," ") | CB5: 儎 | CC5: =_xlfn.XLOOKUP(CB5,対応表!$B:$B,対応表!$C:$C," ") | CD5: 儢 | CE5: =_xlfn.XLOOKUP(CD5,対応表!$B:$B,対応表!$C:$C," ") | CF5: 儶 | CG5: =_xlfn.XLOOKUP(CF5,対応表!$B:$B,対応表!$C:$C," ") | CH5: 兊 | CI5: =_xlfn.XLOOKUP(CH5,対応表!$B:$B,対応表!$C:$C," ") -> 果? | CJ5: 兞 | CK5: =_xlfn.XLOOKUP(CJ5,対応表!$B:$B,対応表!$C:$C," ") | CL5: 兲 | CM5: =_xlfn.XLOOKUP(CL5,対応表!$B:$B,対応表!$C:$C," ") | CN5: 円 | CO5: =_xlfn.XLOOKUP(CN5,対応表!$B:$B,対応表!$C:$C," ") | CP5: 冚 | CQ5: =_xlfn.XLOOKUP(CP5,対応表!$B:$B,対応表!$C:$C," ") | CR5: 冮 | CS5: =_xlfn.XLOOKUP(CR5,対応表!$B:$B,対応表!$C:$C," ") | CT5: 凂 | CU5: =_xlfn.XLOOKUP(CT5,対応表!$B:$B,対応表!$C:$C,"影") -> 影 | CV5: 凖 | CW5: =_xlfn.XLOOKUP(CV5,対応表!$B:$B,対応表!$C:$C," ") | CX5: 凪 | CY5: =_xlfn.XLOOKUP(CX5,対応表!$B:$B,対応表!$C:$C," ") -> 断? | CZ5: 凾 | DA5: =_xlfn.XLOOKUP(CZ5,対応表!$B:$B,対応表!$C:$C," ") -> 交? | DB5: 划 | DC5: =_xlfn.XLOOKUP(DB5,対応表!$B:$B,対応表!$C:$C," ") -> 置 | DD5: 刦 | DE5: =_xlfn.XLOOKUP(DD5,対応表!$B:$B,対応表!$C:$C," ") | DF5: 刺 | DG5: =_xlfn.XLOOKUP(DF5,対応表!$B:$B,対応表!$C:$C," ") | DH5: 剎 | DI5: =_xlfn.XLOOKUP(DH5,対応表!$B:$B,対応表!$C:$C," ") -> 月 | DJ5: 剢 | DK5: =_xlfn.XLOOKUP(DJ5,対応表!$B:$B,対応表!$C:$C," ") | DL5: 剶 | DM5: =_xlfn.XLOOKUP(DL5,対応表!$B:$B,対応表!$C:$C," ") | DN5: 劊 | DO5: =_xlfn.XLOOKUP(DN5,対応表!$B:$B,対応表!$C:$C," ") | DP5: 办 | DQ5: =_xlfn.XLOOKUP(DP5,対応表!$B:$B,対応表!$C:$C," ") | DR5: 劲 | DS5: =_xlfn.XLOOKUP(DR5,対応表!$B:$B,対応表!$C:$C," ") | DT5: 勆 | DU5: =_xlfn.XLOOKUP(DT5,対応表!$B:$B,対応表!$C:$C," ") | DV5: 勚 | DW5: =_xlfn.XLOOKUP(DV5,対応表!$B:$B,対応表!$C:$C," ") | DX5: 勮 | DY5: =_xlfn.XLOOKUP(DX5,対応表!$B:$B,対応表!$C:$C," ") -> 必 | DZ5: 匂 | EA5: =_xlfn.XLOOKUP(DZ5,対応表!$B:$B,対応表!$C:$C," ") | EB5: 化 | EC5: =_xlfn.XLOOKUP(EB5,対応表!$B:$B,対応表!$C:$C," ") | ED5: 匪 | EE5: =_xlfn.XLOOKUP(ED5,対応表!$B:$B,対応表!$C:$C," ") | EF5: 匾 | EG5: =_xlfn.XLOOKUP(EF5,対応表!$B:$B,対応表!$C:$C," ") | EH5: 卒 | EI5: =_xlfn.XLOOKUP(EH5,対応表!$B:$B,対応表!$C:$C," ") | EJ5: 卦 | EK5: =_xlfn.XLOOKUP(EJ5,対応表!$B:$B,対応表!$C:$C," ")
A6: Ｄ | B6: 七 | C6: =_xlfn.XLOOKUP(B6,対応表!$B:$B,対応表!$C:$C,"書") -> 書? | D6: 丗 | E6: {=_xlfn.XLOOKUP(D6,対応表!$B:B,対応表!$C:C," ")} -> め | F6: 丫 | G6: =_xlfn.XLOOKUP(F6,対応表!$B:$B,対応表!$C:$C," ") | H6: 丿 | I6: =_xlfn.XLOOKUP(H6,対応表!$B:$B,対応表!$C:$C,"け") -> け | J6: 乓 | K6: =_xlfn.XLOOKUP(J6,対応表!$B:$B,対応表!$C:$C," ") | L6: 乧 | M6: =_xlfn.XLOOKUP(L6,対応表!$B:$B,対応表!$C:$C," ") -> 来 | N6: 乻 | O6: =_xlfn.XLOOKUP(N6,対応表!$B:$B,対応表!$C:$C," ") -> 変? | P6: 亏 | Q6: =_xlfn.XLOOKUP(P6,対応表!$B:$B,対応表!$C:$C," ") -> じ | R6: 亣 | S6: =_xlfn.XLOOKUP(R6,対応表!$B:$B,対応表!$C:$C," ") | T6: 亷 | U6: =_xlfn.XLOOKUP(T6,対応表!$B:$B,対応表!$C:$C," ") -> 音 | V6: 介 | W6: =_xlfn.XLOOKUP(V6,対応表!$B:$B,対応表!$C:$C," ") -> [介]? | X6: 仟 | Y6: =_xlfn.XLOOKUP(X6,対応表!$B:$B,対応表!$C:$C," ") | Z6: 仳 | AA6: =_xlfn.XLOOKUP(Z6,対応表!$B:$B,対応表!$C:$C," ") | AB6: 伇 | AC6: =_xlfn.XLOOKUP(AB6,対応表!$B:$B,対応表!$C:$C," ") | AD6: 伛 | AE6: =_xlfn.XLOOKUP(AD6,対応表!$B:$B,対応表!$C:$C," ") -> 合 | AF6: 伯 | AG6: =_xlfn.XLOOKUP(AF6,対応表!$B:$B,対応表!$C:$C," ") | AH6: 佃 | AI6: =_xlfn.XLOOKUP(AH6,対応表!$B:$B,対応表!$C:$C," ") -> 持 | AJ6: 佗 | AK6: =_xlfn.XLOOKUP(AJ6,対応表!$B:$B,対応表!$C:$C," ") | AL6: 佫 | AM6: =_xlfn.XLOOKUP(AL6,対応表!$B:$B,対応表!$C:$C," ") -> 本 | AN6: 使 | AO6: =_xlfn.XLOOKUP(AN6,対応表!$B:$B,対応表!$C:$C," ") | AP6: 侓 | AQ6: =_xlfn.XLOOKUP(AP6,対応表!$B:$B,対応表!$C:$C," ") | AR6: 侧 | AS6: =_xlfn.XLOOKUP(AR6,対応表!$B:$B,対応表!$C:$C," ") | AT6: 侻 | AU6: =_xlfn.XLOOKUP(AT6,対応表!$B:$B,対応表!$C:$C," ") -> [侻]? | AV6: 俏 | AW6: =_xlfn.XLOOKUP(AV6,対応表!$B:$B,対応表!$C:$C," ") | AX6: 俣 | AY6: =_xlfn.XLOOKUP(AX6,対応表!$B:$B,対応表!$C:$C," ") | AZ6: 俷 | BA6: =_xlfn.XLOOKUP(AZ6,対応表!$B:$B,対応表!$C:$C," ") | BB6: 個 | BC6: =_xlfn.XLOOKUP(BB6,対応表!$B:$B,対応表!$C:$C," ") | BD6: 借 | BE6: =_xlfn.XLOOKUP(BD6,対応表!$B:$B,対応表!$C:$C," ") -> 休 | BF6: 倳 | BG6: =_xlfn.XLOOKUP(BF6,対応表!$B:$B,対応表!$C:$C," ") | BH6: 假 | BI6: =_xlfn.XLOOKUP(BH6,対応表!$B:$B,対応表!$C:$C," ") -> 客? | BJ6: 偛 | BK6: =_xlfn.XLOOKUP(BJ6,対応表!$B:$B,対応表!$C:$C," ") | BL6: 偯 | BM6: =_xlfn.XLOOKUP(BL6,対応表!$B:$B,対応表!$C:$C," ") | BN6: 傃 | BO6: =_xlfn.XLOOKUP(BN6,対応表!$B:$B,対応表!$C:$C," ") | BP6: 傗 | BQ6: =_xlfn.XLOOKUP(BP6,対応表!$B:$B,対応表!$C:$C," ") | BR6: 傫 | BS6: =_xlfn.XLOOKUP(BR6,対応表!$B:$B,対応表!$C:$C," ") -> ぱ | BT6: 傿 | BU6: =_xlfn.XLOOKUP(BT6,対応表!$B:$B,対応表!$C:$C," ") | BV6: 僓 | BW6: =_xlfn.XLOOKUP(BV6,対応表!$B:$B,対応表!$C:$C," ") | BX6: 僧 | BY6: =_xlfn.XLOOKUP(BX6,対応表!$B:$B,対応表!$C:$C," ") | BZ6: 僻 | CA6: =_xlfn.XLOOKUP(BZ6,対応表!$B:$B,対応表!$C:$C," ") | CB6: 儏 | CC6: =_xlfn.XLOOKUP(CB6,対応表!$B:$B,対応表!$C:$C," ") -> 関? | CD6: 儣 | CE6: =_xlfn.XLOOKUP(CD6,対応表!$B:$B,対応表!$C:$C," ") | CF6: 儷 | CG6: =_xlfn.XLOOKUP(CF6,対応表!$B:$B,対応表!$C:$C," ") -> 除? | CH6: 克 | CI6: =_xlfn.XLOOKUP(CH6,対応表!$B:$B,対応表!$C:$C," ") | CJ6: 兟 | CK6: =_xlfn.XLOOKUP(CJ6,対応表!$B:$B,対応表!$C:$C," ") | CL6: 关 | CM6: =_xlfn.XLOOKUP(CL6,対応表!$B:$B,対応表!$C:$C," ") -> 軽 | CN6: 冇 | CO6: =_xlfn.XLOOKUP(CN6,対応表!$B:$B,対応表!$C:$C," ") | CP6: 军 | CQ6: =_xlfn.XLOOKUP(CP6,対応表!$B:$B,対応表!$C:$C," ") | CR6: 冯 | CS6: =_xlfn.XLOOKUP(CR6,対応表!$B:$B,対応表!$C:$C," ") -> ざ | CT6: 凃 | CU6: =_xlfn.XLOOKUP(CT6,対応表!$B:$B,対応表!$C:$C," ") -> 封 | CV6: 凗 | CW6: =_xlfn.XLOOKUP(CV6,対応表!$B:$B,対応表!$C:$C," ") -> 過? | CX6: 凫 | CY6: =_xlfn.XLOOKUP(CX6,対応表!$B:$B,対応表!$C:$C," ") | CZ6: 凿 | DA6: =_xlfn.XLOOKUP(CZ6,対応表!$B:$B,対応表!$C:$C," ") | DB6: 刓 | DC6: =_xlfn.XLOOKUP(DB6,対応表!$B:$B,対応表!$C:$C," ") | DD6: 刧 | DE6: =_xlfn.XLOOKUP(DD6,対応表!$B:$B,対応表!$C:$C," ") | DF6: 刻 | DG6: =_xlfn.XLOOKUP(DF6,対応表!$B:$B,対応表!$C:$C," ") -> 首? | DH6: 剏 | DI6: =_xlfn.XLOOKUP(DH6,対応表!$B:$B,対応表!$C:$C," ") | DJ6: 剣 | DK6: =_xlfn.XLOOKUP(DJ6,対応表!$B:$B,対応表!$C:$C," ") | DL6: 剷 | DM6: =_xlfn.XLOOKUP(DL6,対応表!$B:$B,対応表!$C:$C," ") -> 定 | DN6: 劋 | DO6: =_xlfn.XLOOKUP(DN6,対応表!$B:$B,対応表!$C:$C," ") | DP6: 功 | DQ6: =_xlfn.XLOOKUP(DP6,対応表!$B:$B,対応表!$C:$C," ") | DR6: 劳 | DS6: =_xlfn.XLOOKUP(DR6,対応表!$B:$B,対応表!$C:$C," ") | DT6: 勇 | DU6: =_xlfn.XLOOKUP(DT6,対応表!$B:$B,対応表!$C:$C," ") -> 保 | DV6: 勛 | DW6: =_xlfn.XLOOKUP(DV6,対応表!$B:$B,対応表!$C:$C," ") | DX6: 勯 | DY6: =_xlfn.XLOOKUP(DX6,対応表!$B:$B,対応表!$C:$C," ") | DZ6: 匃 | EA6: =_xlfn.XLOOKUP(DZ6,対応表!$B:$B,対応表!$C:$C," ") | EB6: 北 | EC6: =_xlfn.XLOOKUP(EB6,対応表!$B:$B,対応表!$C:$C," ") | ED6: 匫 | EE6: =_xlfn.XLOOKUP(ED6,対応表!$B:$B,対応表!$C:$C," ") | EF6: 匿 | EG6: =_xlfn.XLOOKUP(EF6,対応表!$B:$B,対応表!$C:$C," ") | EH6: 卓 | EI6: =_xlfn.XLOOKUP(EH6,対応表!$B:$B,対応表!$C:$C," ") | EJ6: 卧 | EK6: =_xlfn.XLOOKUP(EJ6,対応表!$B:$B,対応表!$C:$C," ")
A7: Ｅ | B7: 丄 | C7: =_xlfn.XLOOKUP(B7,対応表!$B:$B,対応表!$C:$C," ") -> き | D7: 丘 | E7: {=_xlfn.XLOOKUP(D7,対応表!$B:B,対応表!$C:C,"の")} -> の | F7: 丬 | G7: =_xlfn.XLOOKUP(F7,対応表!$B:$B,対応表!$C:$C," ") | H7: 乀 | I7: =_xlfn.XLOOKUP(H7,対応表!$B:$B,対応表!$C:$C," ") | J7: 乔 | K7: =_xlfn.XLOOKUP(J7,対応表!$B:$B,対応表!$C:$C," ") | L7: 乨 | M7: =_xlfn.XLOOKUP(L7,対応表!$B:$B,対応表!$C:$C,"に") -> に | N7: 乼 | O7: =_xlfn.XLOOKUP(N7,対応表!$B:$B,対応表!$C:$C," ") -> 革? | P7: 亐 | Q7: =_xlfn.XLOOKUP(P7,対応表!$B:$B,対応表!$C:$C," ") | R7: 交 | S7: =_xlfn.XLOOKUP(R7,対応表!$B:$B,対応表!$C:$C," ") | T7: 亸 | U7: =_xlfn.XLOOKUP(T7,対応表!$B:$B,対応表!$C:$C," ") | V7: 仌 | W7: =_xlfn.XLOOKUP(V7,対応表!$B:$B,対応表!$C:$C," ") | X7: 仠 | Y7: =_xlfn.XLOOKUP(X7,対応表!$B:$B,対応表!$C:$C," ") | Z7: 仴 | AA7: =_xlfn.XLOOKUP(Z7,対応表!$B:$B,対応表!$C:$C," ") | AB7: 伈 | AC7: =_xlfn.XLOOKUP(AB7,対応表!$B:$B,対応表!$C:$C," ") -> 落 | AD7: 伜 | AE7: =_xlfn.XLOOKUP(AD7,対応表!$B:$B,対応表!$C:$C," ") | AF7: 估 | AG7: =_xlfn.XLOOKUP(AF7,対応表!$B:$B,対応表!$C:$C," ") | AH7: 佄 | AI7: =_xlfn.XLOOKUP(AH7,対応表!$B:$B,対応表!$C:$C," ") -> つ | AJ7: 佘 | AK7: =_xlfn.XLOOKUP(AJ7,対応表!$B:$B,対応表!$C:$C," ") -> 作 | AL7: 佬 | AM7: =_xlfn.XLOOKUP(AL7,対応表!$B:$B,対応表!$C:$C," ") -> 壁? | AN7: 侀 | AO7: =_xlfn.XLOOKUP(AN7,対応表!$B:$B,対応表!$C:$C," ") | AP7: 侔 | AQ7: =_xlfn.XLOOKUP(AP7,対応表!$B:$B,対応表!$C:$C," ") -> ぇ | AR7: 侨 | AS7: =_xlfn.XLOOKUP(AR7,対応表!$B:$B,対応表!$C:$C," ") | AT7: 侼 | AU7: =_xlfn.XLOOKUP(AT7,対応表!$B:$B,対応表!$C:$C," ") | AV7: 俐 | AW7: =_xlfn.XLOOKUP(AV7,対応表!$B:$B,対応表!$C:$C," ") | AX7: 俤 | AY7: =_xlfn.XLOOKUP(AX7,対応表!$B:$B,対応表!$C:$C," ") | AZ7: 俸 | BA7: =_xlfn.XLOOKUP(AZ7,対応表!$B:$B,対応表!$C:$C," ") | BB7: 倌 | BC7: =_xlfn.XLOOKUP(BB7,対応表!$B:$B,対応表!$C:$C," ") | BD7: 倠 | BE7: =_xlfn.XLOOKUP(BD7,対応表!$B:$B,対応表!$C:$C," ") -> 養 | BF7: 倴 | BG7: =_xlfn.XLOOKUP(BF7,対応表!$B:$B,対応表!$C:$C," ") | BH7: 偈 | BI7: =_xlfn.XLOOKUP(BH7,対応表!$B:$B,対応表!$C:$C," ") | BJ7: 停 | BK7: =_xlfn.XLOOKUP(BJ7,対応表!$B:$B,対応表!$C:$C," ") | BL7: 偰 | BM7: =_xlfn.XLOOKUP(BL7,対応表!$B:$B,対応表!$C:$C," ") | BN7: 傄 | BO7: =_xlfn.XLOOKUP(BN7,対応表!$B:$B,対応表!$C:$C," ") | BP7: 傘 | BQ7: =_xlfn.XLOOKUP(BP7,対応表!$B:$B,対応表!$C:$C," ") | BR7: 催 | BS7: =_xlfn.XLOOKUP(BR7,対応表!$B:$B,対応表!$C:$C," ") | BT7: 僀 | BU7: =_xlfn.XLOOKUP(BT7,対応表!$B:$B,対応表!$C:$C," ") | BV7: 僔 | BW7: =_xlfn.XLOOKUP(BV7,対応表!$B:$B,対応表!$C:$C," ") | BX7: 僨 | BY7: =_xlfn.XLOOKUP(BX7,対応表!$B:$B,対応表!$C:$C," ") | BZ7: 僼 | CA7: =_xlfn.XLOOKUP(BZ7,対応表!$B:$B,対応表!$C:$C," ") | CB7: 儐 | CC7: =_xlfn.XLOOKUP(CB7,対応表!$B:$B,対応表!$C:$C," ") -> 係? | CD7: 儤 | CE7: =_xlfn.XLOOKUP(CD7,対応表!$B:$B,対応表!$C:$C," ") | CF7: 儸 | CG7: =_xlfn.XLOOKUP(CF7,対応表!$B:$B,対応表!$C:$C," ") | CH7: 兌 | CI7: =_xlfn.XLOOKUP(CH7,対応表!$B:$B,対応表!$C:$C," ") | CJ7: 兠 | CK7: =_xlfn.XLOOKUP(CJ7,対応表!$B:$B,対応表!$C:$C," ") | CL7: 兴 | CM7: =_xlfn.XLOOKUP(CL7,対応表!$B:$B,対応表!$C:$C," ") | CN7: 冈 | CO7: =_xlfn.XLOOKUP(CN7,対応表!$B:$B,対応表!$C:$C," ") | CP7: 农 | CQ7: =_xlfn.XLOOKUP(CP7,対応表!$B:$B,対応表!$C:$C," ") | CR7: 冰 | CS7: =_xlfn.XLOOKUP(CR7,対応表!$B:$B,対応表!$C:$C," ") | CT7: 凄 | CU7: =_xlfn.XLOOKUP(CT7,対応表!$B:$B,対応表!$C:$C," ") -> 房? | CV7: 凘 | CW7: =_xlfn.XLOOKUP(CV7,対応表!$B:$B,対応表!$C:$C," ") -> [凘]? | CX7: 凬 | CY7: =_xlfn.XLOOKUP(CX7,対応表!$B:$B,対応表!$C:$C," ") | CZ7: 刀 | DA7: =_xlfn.XLOOKUP(CZ7,対応表!$B:$B,対応表!$C:$C," ") | DB7: 刔 | DC7: =_xlfn.XLOOKUP(DB7,対応表!$B:$B,対応表!$C:$C," ") | DD7: 刨 | DE7: =_xlfn.XLOOKUP(DD7,対応表!$B:$B,対応表!$C:$C," ") | DF7: 刼 | DG7: =_xlfn.XLOOKUP(DF7,対応表!$B:$B,対応表!$C:$C," ") | DH7: 剐 | DI7: =_xlfn.XLOOKUP(DH7,対応表!$B:$B,対応表!$C:$C," ") | DJ7: 剤 | DK7: =_xlfn.XLOOKUP(DJ7,対応表!$B:$B,対応表!$C:$C," ") | DL7: 剸 | DM7: =_xlfn.XLOOKUP(DL7,対応表!$B:$B,対応表!$C:$C," ") -> 文? | DN7: 劌 | DO7: =_xlfn.XLOOKUP(DN7,対応表!$B:$B,対応表!$C:$C," ") | DP7: 加 | DQ7: =_xlfn.XLOOKUP(DP7,対応表!$B:$B,対応表!$C:$C," ") | DR7: 労 | DS7: =_xlfn.XLOOKUP(DR7,対応表!$B:$B,対応表!$C:$C," ") | DT7: 勈 | DU7: =_xlfn.XLOOKUP(DT7,対応表!$B:$B,対応表!$C:$C," ") | DV7: 勜 | DW7: =_xlfn.XLOOKUP(DV7,対応表!$B:$B,対応表!$C:$C," ") -> 訪 | DX7: 勰 | DY7: =_xlfn.XLOOKUP(DX7,対応表!$B:$B,対応表!$C:$C," ") | DZ7: 匄 | EA7: =_xlfn.XLOOKUP(DZ7,対応表!$B:$B,対応表!$C:$C," ") -> 選 | EB7: 匘 | EC7: =_xlfn.XLOOKUP(EB7,対応表!$B:$B,対応表!$C:$C," ") | ED7: 匬 | EE7: =_xlfn.XLOOKUP(ED7,対応表!$B:$B,対応表!$C:$C," ") | EF7: 區 | EG7: =_xlfn.XLOOKUP(EF7,対応表!$B:$B,対応表!$C:$C," ") | EH7: 協 | EI7: =_xlfn.XLOOKUP(EH7,対応表!$B:$B,対応表!$C:$C," ") | EJ7: 卨 | EK7: =_xlfn.XLOOKUP(EJ7,対応表!$B:$B,対応表!$C:$C," ")
A8: Ｆ | B8: 丅 | C8: =_xlfn.XLOOKUP(B8,対応表!$B:$B,対応表!$C:$C," ") -> 記 | D8: 丙 | E8: {=_xlfn.XLOOKUP(D8,対応表!$B:B,対応表!$C:C," ")} -> 言 | F8: 中 | G8: =_xlfn.XLOOKUP(F8,対応表!$B:$B,対応表!$C:$C," ") | H8: 乁 | I8: =_xlfn.XLOOKUP(H8,対応表!$B:$B,対応表!$C:$C," ") | J8: 乕 | K8: =_xlfn.XLOOKUP(J8,対応表!$B:$B,対応表!$C:$C," ") | L8: 乩 | M8: =_xlfn.XLOOKUP(L8,対応表!$B:$B,対応表!$C:$C," ") -> 取 | N8: 乽 | O8: =_xlfn.XLOOKUP(N8,対応表!$B:$B,対応表!$C:$C," ") | P8: 云 | Q8: =_xlfn.XLOOKUP(P8,対応表!$B:$B,対応表!$C:$C," ") -> 出 | R8: 亥 | S8: =_xlfn.XLOOKUP(R8,対応表!$B:$B,対応表!$C:$C," ") | T8: 亹 | U8: =_xlfn.XLOOKUP(T8,対応表!$B:$B,対応表!$C:$C," ") | V8: 仍 | W8: =_xlfn.XLOOKUP(V8,対応表!$B:$B,対応表!$C:$C," ") | X8: 仡 | Y8: =_xlfn.XLOOKUP(X8,対応表!$B:$B,対応表!$C:$C," ") -> 終 | Z8: 仵 | AA8: =_xlfn.XLOOKUP(Z8,対応表!$B:$B,対応表!$C:$C," ") | AB8: 伉 | AC8: =_xlfn.XLOOKUP(AB8,対応表!$B:$B,対応表!$C:$C," ") | AD8: 伝 | AE8: =_xlfn.XLOOKUP(AD8,対応表!$B:$B,対応表!$C:$C," ") | AF8: 伱 | AG8: =_xlfn.XLOOKUP(AF8,対応表!$B:$B,対応表!$C:$C," ") | AH8: 佅 | AI8: =_xlfn.XLOOKUP(AH8,対応表!$B:$B,対応表!$C:$C," ") | AJ8: 余 | AK8: =_xlfn.XLOOKUP(AJ8,対応表!$B:$B,対応表!$C:$C," ") | AL8: 佭 | AM8: =_xlfn.XLOOKUP(AL8,対応表!$B:$B,対応表!$C:$C,"に") -> に | AN8: 侁 | AO8: =_xlfn.XLOOKUP(AN8,対応表!$B:$B,対応表!$C:$C," ") -> 止? | AP8: 侕 | AQ8: =_xlfn.XLOOKUP(AP8,対応表!$B:$B,対応表!$C:$C," ") -> ん | AR8: 侩 | AS8: =_xlfn.XLOOKUP(AR8,対応表!$B:$B,対応表!$C:$C," ") | AT8: 侽 | AU8: =_xlfn.XLOOKUP(AT8,対応表!$B:$B,対応表!$C:$C," ") | AV8: 俑 | AW8: =_xlfn.XLOOKUP(AV8,対応表!$B:$B,対応表!$C:$C," ") | AX8: 俥 | AY8: =_xlfn.XLOOKUP(AX8,対応表!$B:$B,対応表!$C:$C," ") -> ぐ | AZ8: 俹 | BA8: =_xlfn.XLOOKUP(AZ8,対応表!$B:$B,対応表!$C:$C," ") -> 道 | BB8: 倍 | BC8: =_xlfn.XLOOKUP(BB8,対応表!$B:$B,対応表!$C:$C," ") -> 良 | BD8: 倡 | BE8: =_xlfn.XLOOKUP(BD8,対応表!$B:$B,対応表!$C:$C," ") | BF8: 倵 | BG8: =_xlfn.XLOOKUP(BF8,対応表!$B:$B,対応表!$C:$C," ") | BH8: 偉 | BI8: =_xlfn.XLOOKUP(BH8,対応表!$B:$B,対応表!$C:$C," ") -> 丁 | BJ8: 偝 | BK8: =_xlfn.XLOOKUP(BJ8,対応表!$B:$B,対応表!$C:$C," ") | BL8: 偱 | BM8: =_xlfn.XLOOKUP(BL8,対応表!$B:$B,対応表!$C:$C," ") | BN8: 傅 | BO8: =_xlfn.XLOOKUP(BN8,対応表!$B:$B,対応表!$C:$C," ") | BP8: 備 | BQ8: =_xlfn.XLOOKUP(BP8,対応表!$B:$B,対応表!$C:$C," ") -> 新 | BR8: 傭 | BS8: =_xlfn.XLOOKUP(BR8,対応表!$B:$B,対応表!$C:$C," ") | BT8: 僁 | BU8: =_xlfn.XLOOKUP(BT8,対応表!$B:$B,対応表!$C:$C," ") | BV8: 僕 | BW8: =_xlfn.XLOOKUP(BV8,対応表!$B:$B,対応表!$C:$C," ") | BX8: 僩 | BY8: =_xlfn.XLOOKUP(BX8,対応表!$B:$B,対応表!$C:$C," ") | BZ8: 僽 | CA8: =_xlfn.XLOOKUP(BZ8,対応表!$B:$B,対応表!$C:$C," ") | CB8: 儑 | CC8: =_xlfn.XLOOKUP(CB8,対応表!$B:$B,対応表!$C:$C," ") | CD8: 儥 | CE8: =_xlfn.XLOOKUP(CD8,対応表!$B:$B,対応表!$C:$C," ") | CF8: 儹 | CG8: =_xlfn.XLOOKUP(CF8,対応表!$B:$B,対応表!$C:$C," ") -> 上 | CH8: 免 | CI8: =_xlfn.XLOOKUP(CH8,対応表!$B:$B,対応表!$C:$C," ") | CJ8: 兡 | CK8: =_xlfn.XLOOKUP(CJ8,対応表!$B:$B,対応表!$C:$C," ") -> ご | CL8: 兵 | CM8: =_xlfn.XLOOKUP(CL8,対応表!$B:$B,対応表!$C:$C," ") | CN8: 冉 | CO8: =_xlfn.XLOOKUP(CN8,対応表!$B:$B,対応表!$C:$C," ") | CP8: 冝 | CQ8: =_xlfn.XLOOKUP(CP8,対応表!$B:$B,対応表!$C:$C," ") | CR8: 冱 | CS8: =_xlfn.XLOOKUP(CR8,対応表!$B:$B,対応表!$C:$C," ") | CT8: 凅 | CU8: =_xlfn.XLOOKUP(CT8,対応表!$B:$B,対応表!$C:$C," ") | CV8: 凙 | CW8: =_xlfn.XLOOKUP(CV8,対応表!$B:$B,対応表!$C:$C," ") | CX8: 凭 | CY8: =_xlfn.XLOOKUP(CX8,対応表!$B:$B,対応表!$C:$C," ") -> 力 | CZ8: 刁 | DA8: =_xlfn.XLOOKUP(CZ8,対応表!$B:$B,対応表!$C:$C," ") | DB8: 刕 | DC8: =_xlfn.XLOOKUP(DB8,対応表!$B:$B,対応表!$C:$C," ") | DD8: 利 | DE8: =_xlfn.XLOOKUP(DD8,対応表!$B:$B,対応表!$C:$C," ") | DF8: 刽 | DG8: =_xlfn.XLOOKUP(DF8,対応表!$B:$B,対応表!$C:$C," ") | DH8: 剑 | DI8: =_xlfn.XLOOKUP(DH8,対応表!$B:$B,対応表!$C:$C," ") -> 流? | DJ8: 剥 | DK8: =_xlfn.XLOOKUP(DJ8,対応表!$B:$B,対応表!$C:$C," ") | DL8: 剹 | DM8: =_xlfn.XLOOKUP(DL8,対応表!$B:$B,対応表!$C:$C," ") | DN8: 劍 | DO8: =_xlfn.XLOOKUP(DN8,対応表!$B:$B,対応表!$C:$C," ") | DP8: 务 | DQ8: =_xlfn.XLOOKUP(DP8,対応表!$B:$B,対応表!$C:$C," ") | DR8: 劵 | DS8: =_xlfn.XLOOKUP(DR8,対応表!$B:$B,対応表!$C:$C," ") | DT8: 勉 | DU8: =_xlfn.XLOOKUP(DT8,対応表!$B:$B,対応表!$C:$C," ") | DV8: 勝 | DW8: =_xlfn.XLOOKUP(DV8,対応表!$B:$B,対応表!$C:$C," ") | DX8: 勱 | DY8: =_xlfn.XLOOKUP(DX8,対応表!$B:$B,対応表!$C:$C," ") | DZ8: 包 | EA8: =_xlfn.XLOOKUP(DZ8,対応表!$B:$B,対応表!$C:$C," ") | EB8: 匙 | EC8: =_xlfn.XLOOKUP(EB8,対応表!$B:$B,対応表!$C:$C," ") -> 散? | ED8: 匭 | EE8: =_xlfn.XLOOKUP(ED8,対応表!$B:$B,対応表!$C:$C," ") | EF8: 十 | EG8: =_xlfn.XLOOKUP(EF8,対応表!$B:$B,対応表!$C:$C," ") | EH8: 单 | EI8: =_xlfn.XLOOKUP(EH8,対応表!$B:$B,対応表!$C:$C," ") | EJ8: 卩 | EK8: =_xlfn.XLOOKUP(EJ8,対応表!$B:$B,対応表!$C:$C," ")
A9: Ｇ | B9: 丆 | C9: =_xlfn.XLOOKUP(B9,対応表!$B:$B,対応表!$C:$C," ") -> す | D9: 业 | E9: {=_xlfn.XLOOKUP(D9,対応表!$B:B,対応表!$C:C,"葉")} -> 葉? | F9: 丮 | G9: =_xlfn.XLOOKUP(F9,対応表!$B:$B,対応表!$C:$C," ") -> 活 | H9: 乂 | I9: =_xlfn.XLOOKUP(H9,対応表!$B:$B,対応表!$C:$C," ") | J9: 乖 | K9: =_xlfn.XLOOKUP(J9,対応表!$B:$B,対応表!$C:$C," ") -> を | L9: 乪 | M9: =_xlfn.XLOOKUP(L9,対応表!$B:$B,対応表!$C:$C,"り") -> り | N9: 乾 | O9: =_xlfn.XLOOKUP(N9,対応表!$B:$B,対応表!$C:$C," ") | P9: 互 | Q9: =_xlfn.XLOOKUP(P9,対応表!$B:$B,対応表!$C:$C," ") | R9: 亦 | S9: =_xlfn.XLOOKUP(R9,対応表!$B:$B,対応表!$C:$C," ") | T9: 人 | U9: =_xlfn.XLOOKUP(T9,対応表!$B:$B,対応表!$C:$C," ") | V9: 从 | W9: =_xlfn.XLOOKUP(V9,対応表!$B:$B,対応表!$C:$C," ") | X9: 仢 | Y9: =_xlfn.XLOOKUP(X9,対応表!$B:$B,対応表!$C:$C," ") -> ぞ | Z9: 件 | AA9: =_xlfn.XLOOKUP(Z9,対応表!$B:$B,対応表!$C:$C," ") | AB9: 伊 | AC9: =_xlfn.XLOOKUP(AB9,対応表!$B:$B,対応表!$C:$C," ") -> 導? | AD9: 伞 | AE9: =_xlfn.XLOOKUP(AD9,対応表!$B:$B,対応表!$C:$C," ") | AF9: 伲 | AG9: =_xlfn.XLOOKUP(AF9,対応表!$B:$B,対応表!$C:$C," ") | AH9: 但 | AI9: =_xlfn.XLOOKUP(AH9,対応表!$B:$B,対応表!$C:$C," ") | AJ9: 佚 | AK9: =_xlfn.XLOOKUP(AJ9,対応表!$B:$B,対応表!$C:$C," ") | AL9: 佮 | AM9: =_xlfn.XLOOKUP(AL9,対応表!$B:$B,対応表!$C:$C," ") -> 向 | AN9: 侂 | AO9: =_xlfn.XLOOKUP(AN9,対応表!$B:$B,対応表!$C:$C," ") -> 様? | AP9: 侖 | AQ9: =_xlfn.XLOOKUP(AP9,対応表!$B:$B,対応表!$C:$C," ") | AR9: 侪 | AS9: =_xlfn.XLOOKUP(AR9,対応表!$B:$B,対応表!$C:$C," ") | AT9: 侾 | AU9: =_xlfn.XLOOKUP(AT9,対応表!$B:$B,対応表!$C:$C," ") | AV9: 俒 | AW9: =_xlfn.XLOOKUP(AV9,対応表!$B:$B,対応表!$C:$C," ") | AX9: 俦 | AY9: =_xlfn.XLOOKUP(AX9,対応表!$B:$B,対応表!$C:$C," ") | AZ9: 俺 | BA9: =_xlfn.XLOOKUP(AZ9,対応表!$B:$B,対応表!$C:$C,"に") -> に | BB9: 倎 | BC9: =_xlfn.XLOOKUP(BB9,対応表!$B:$B,対応表!$C:$C,"く") -> く | BD9: 倢 | BE9: =_xlfn.XLOOKUP(BD9,対応表!$B:$B,対応表!$C:$C," ") | BF9: 倶 | BG9: =_xlfn.XLOOKUP(BF9,対応表!$B:$B,対応表!$C:$C," ") | BH9: 偊 | BI9: =_xlfn.XLOOKUP(BH9,対応表!$B:$B,対応表!$C:$C," ") -> 重 | BJ9: 偞 | BK9: =_xlfn.XLOOKUP(BJ9,対応表!$B:$B,対応表!$C:$C," ") | BL9: 偲 | BM9: =_xlfn.XLOOKUP(BL9,対応表!$B:$B,対応表!$C:$C," ") | BN9: 傆 | BO9: =_xlfn.XLOOKUP(BN9,対応表!$B:$B,対応表!$C:$C," ") | BP9: 傚 | BQ9: =_xlfn.XLOOKUP(BP9,対応表!$B:$B,対応表!$C:$C," ") -> 祝 | BR9: 傮 | BS9: =_xlfn.XLOOKUP(BR9,対応表!$B:$B,対応表!$C:$C," ") | BT9: 僂 | BU9: =_xlfn.XLOOKUP(BT9,対応表!$B:$B,対応表!$C:$C," ") | BV9: 僖 | BW9: =_xlfn.XLOOKUP(BV9,対応表!$B:$B,対応表!$C:$C," ") | BX9: 僪 | BY9: =_xlfn.XLOOKUP(BX9,対応表!$B:$B,対応表!$C:$C," ") | BZ9: 僾 | CA9: =_xlfn.XLOOKUP(BZ9,対応表!$B:$B,対応表!$C:$C," ") | CB9: 儒 | CC9: =_xlfn.XLOOKUP(CB9,対応表!$B:$B,対応表!$C:$C," ") | CD9: 儦 | CE9: =_xlfn.XLOOKUP(CD9,対応表!$B:$B,対応表!$C:$C," ") | CF9: 儺 | CG9: =_xlfn.XLOOKUP(CF9,対応表!$B:$B,対応表!$C:$C," ") -> 下 | CH9: 兎 | CI9: =_xlfn.XLOOKUP(CH9,対応表!$B:$B,対応表!$C:$C," ") -> 広 | CJ9: 兢 | CK9: =_xlfn.XLOOKUP(CJ9,対応表!$B:$B,対応表!$C:$C," ") | CL9: 其 | CM9: =_xlfn.XLOOKUP(CL9,対応表!$B:$B,対応表!$C:$C," ") | CN9: 冊 | CO9: =_xlfn.XLOOKUP(CN9,対応表!$B:$B,対応表!$C:$C," ") | CP9: 冞 | CQ9: =_xlfn.XLOOKUP(CP9,対応表!$B:$B,対応表!$C:$C," ") -> 息? | CR9: 冲 | CS9: =_xlfn.XLOOKUP(CR9,対応表!$B:$B,対応表!$C:$C," ") | CT9: 准 | CU9: =_xlfn.XLOOKUP(CT9,対応表!$B:$B,対応表!$C:$C," ") -> 収? | CV9: 凚 | CW9: =_xlfn.XLOOKUP(CV9,対応表!$B:$B,対応表!$C:$C," ") | CX9: 凮 | CY9: =_xlfn.XLOOKUP(CX9,対応表!$B:$B,対応表!$C:$C," ") | CZ9: 刂 | DA9: =_xlfn.XLOOKUP(CZ9,対応表!$B:$B,対応表!$C:$C," ") | DB9: 刖 | DC9: =_xlfn.XLOOKUP(DB9,対応表!$B:$B,対応表!$C:$C," ") | DD9: 刪 | DE9: =_xlfn.XLOOKUP(DD9,対応表!$B:$B,対応表!$C:$C," ") | DF9: 刾 | DG9: =_xlfn.XLOOKUP(DF9,対応表!$B:$B,対応表!$C:$C," ") | DH9: 剒 | DI9: =_xlfn.XLOOKUP(DH9,対応表!$B:$B,対応表!$C:$C," ") | DJ9: 剦 | DK9: =_xlfn.XLOOKUP(DJ9,対応表!$B:$B,対応表!$C:$C," ") | DL9: 剺 | DM9: =_xlfn.XLOOKUP(DL9,対応表!$B:$B,対応表!$C:$C," ") -> 印? | DN9: 劎 | DO9: =_xlfn.XLOOKUP(DN9,対応表!$B:$B,対応表!$C:$C," ") | DP9: 劢 | DQ9: =_xlfn.XLOOKUP(DP9,対応表!$B:$B,対応表!$C:$C," ") | DR9: 劶 | DS9: =_xlfn.XLOOKUP(DR9,対応表!$B:$B,対応表!$C:$C," ") | DT9: 勊 | DU9: =_xlfn.XLOOKUP(DT9,対応表!$B:$B,対応表!$C:$C," ") | DV9: 勞 | DW9: =_xlfn.XLOOKUP(DV9,対応表!$B:$B,対応表!$C:$C," ") | DX9: 勲 | DY9: =_xlfn.XLOOKUP(DX9,対応表!$B:$B,対応表!$C:$C," ") | DZ9: 匆 | EA9: =_xlfn.XLOOKUP(DZ9,対応表!$B:$B,対応表!$C:$C," ") | EB9: 匚 | EC9: =_xlfn.XLOOKUP(EB9,対応表!$B:$B,対応表!$C:$C," ") | ED9: 匮 | EE9: =_xlfn.XLOOKUP(ED9,対応表!$B:$B,対応表!$C:$C," ") | EF9: 卂 | EG9: =_xlfn.XLOOKUP(EF9,対応表!$B:$B,対応表!$C:$C," ") | EH9: 卖 | EI9: =_xlfn.XLOOKUP(EH9,対応表!$B:$B,対応表!$C:$C," ") | EJ9: 卪 | EK9: =_xlfn.XLOOKUP(EJ9,対応表!$B:$B,対応表!$C:$C," ")
A10: Ｈ | B10: 万 | C10: =_xlfn.XLOOKUP(B10,対応表!$B:$B,対応表!$C:$C," ") -> は | D10: 丛 | E10: {=_xlfn.XLOOKUP(D10,対応表!$B:B,対応表!$C:C,"で")} -> で | F10: 丯 | G10: =_xlfn.XLOOKUP(F10,対応表!$B:$B,対応表!$C:$C," ") | H10: 乃 | I10: =_xlfn.XLOOKUP(H10,対応表!$B:$B,対応表!$C:$C," ") | J10: 乗 | K10: =_xlfn.XLOOKUP(J10,対応表!$B:$B,対応表!$C:$C," ") | L10: 乫 | M10: =_xlfn.XLOOKUP(L10,対応表!$B:$B,対応表!$C:$C," ") -> 残 | N10: 乿 | O10: =_xlfn.XLOOKUP(N10,対応表!$B:$B,対応表!$C:$C," ") | P10: 亓 | Q10: =_xlfn.XLOOKUP(P10,対応表!$B:$B,対応表!$C:$C," ") | R10: 产 | S10: =_xlfn.XLOOKUP(R10,対応表!$B:$B,対応表!$C:$C," ") | T10: 亻 | U10: =_xlfn.XLOOKUP(T10,対応表!$B:$B,対応表!$C:$C," ") | V10: 仏 | W10: =_xlfn.XLOOKUP(V10,対応表!$B:$B,対応表!$C:$C," ") | X10: 代 | Y10: =_xlfn.XLOOKUP(X10,対応表!$B:$B,対応表!$C:$C," ") -> い | Z10: 价 | AA10: =_xlfn.XLOOKUP(Z10,対応表!$B:$B,対応表!$C:$C," ") | AB10: 伋 | AC10: =_xlfn.XLOOKUP(AB10,対応表!$B:$B,対応表!$C:$C," ") | AD10: 伟 | AE10: =_xlfn.XLOOKUP(AD10,対応表!$B:$B,対応表!$C:$C," ") | AF10: 伳 | AG10: =_xlfn.XLOOKUP(AF10,対応表!$B:$B,対応表!$C:$C," ") -> 名 | AH10: 佇 | AI10: =_xlfn.XLOOKUP(AH10,対応表!$B:$B,対応表!$C:$C," ") | AJ10: 佛 | AK10: =_xlfn.XLOOKUP(AJ10,対応表!$B:$B,対応表!$C:$C," ") | AL10: 佯 | AM10: =_xlfn.XLOOKUP(AL10,対応表!$B:$B,対応表!$C:$C,"か") -> か | AN10: 侃 | AO10: =_xlfn.XLOOKUP(AN10,対応表!$B:$B,対応表!$C:$C," ") | AP10: 侗 | AQ10: =_xlfn.XLOOKUP(AP10,対応表!$B:$B,対応表!$C:$C," ") | AR10: 侫 | AS10: =_xlfn.XLOOKUP(AR10,対応表!$B:$B,対応表!$C:$C," ") -> 知 | AT10: 便 | AU10: =_xlfn.XLOOKUP(AT10,対応表!$B:$B,対応表!$C:$C," ") | AV10: 俓 | AW10: =_xlfn.XLOOKUP(AV10,対応表!$B:$B,対応表!$C:$C," ") | AX10: 俧 | AY10: =_xlfn.XLOOKUP(AX10,対応表!$B:$B,対応表!$C:$C," ") | AZ10: 俻 | BA10: =_xlfn.XLOOKUP(AZ10,対応表!$B:$B,対応表!$C:$C," ") -> 迷 | BB10: 倏 | BC10: =_xlfn.XLOOKUP(BB10,対応表!$B:$B,対応表!$C:$C," ") -> 店 | BD10: 倣 | BE10: =_xlfn.XLOOKUP(BD10,対応表!$B:$B,対応表!$C:$C," ") | BF10: 倷 | BG10: =_xlfn.XLOOKUP(BF10,対応表!$B:$B,対応表!$C:$C," ") | BH10: 偋 | BI10: =_xlfn.XLOOKUP(BH10,対応表!$B:$B,対応表!$C:$C," ") | BJ10: 偟 | BK10: =_xlfn.XLOOKUP(BJ10,対応表!$B:$B,対応表!$C:$C," ") | BL10: 偳 | BM10: =_xlfn.XLOOKUP(BL10,対応表!$B:$B,対応表!$C:$C," ") | BN10: 傇 | BO10: =_xlfn.XLOOKUP(BN10,対応表!$B:$B,対応表!$C:$C," ") | BP10: 傛 | BQ10: =_xlfn.XLOOKUP(BP10,対応表!$B:$B,対応表!$C:$C," ") | BR10: 傯 | BS10: =_xlfn.XLOOKUP(BR10,対応表!$B:$B,対応表!$C:$C," ") -> ー | BT10: 僃 | BU10: =_xlfn.XLOOKUP(BT10,対応表!$B:$B,対応表!$C:$C," ") | BV10: 僗 | BW10: =_xlfn.XLOOKUP(BV10,対応表!$B:$B,対応表!$C:$C," ") | BX10: 僫 | BY10: =_xlfn.XLOOKUP(BX10,対応表!$B:$B,対応表!$C:$C," ") | BZ10: 僿 | CA10: =_xlfn.XLOOKUP(BZ10,対応表!$B:$B,対応表!$C:$C," ") | CB10: 儓 | CC10: =_xlfn.XLOOKUP(CB10,対応表!$B:$B,対応表!$C:$C," ") | CD10: 儧 | CE10: =_xlfn.XLOOKUP(CD10,対応表!$B:$B,対応表!$C:$C," ") | CF10: 儻 | CG10: =_xlfn.XLOOKUP(CF10,対応表!$B:$B,対応表!$C:$C,"の") -> の | CH10: 兏 | CI10: =_xlfn.XLOOKUP(CH10,対応表!$B:$B,対応表!$C:$C," ") | CJ10: 兣 | CK10: =_xlfn.XLOOKUP(CJ10,対応表!$B:$B,対応表!$C:$C," ") | CL10: 具 | CM10: =_xlfn.XLOOKUP(CL10,対応表!$B:$B,対応表!$C:$C," ") | CN10: 冋 | CO10: =_xlfn.XLOOKUP(CN10,対応表!$B:$B,対応表!$C:$C," ") | CP10: 冟 | CQ10: =_xlfn.XLOOKUP(CP10,対応表!$B:$B,対応表!$C:$C," ") -> づ/付? | CR10: 决 | CS10: =_xlfn.XLOOKUP(CR10,対応表!$B:$B,対応表!$C:$C," ") | CT10: 凇 | CU10: =_xlfn.XLOOKUP(CT10,対応表!$B:$B,対応表!$C:$C," ") -> 監? | CV10: 凛 | CW10: =_xlfn.XLOOKUP(CV10,対応表!$B:$B,対応表!$C:$C," ") | CX10: 凯 | CY10: =_xlfn.XLOOKUP(CX10,対応表!$B:$B,対応表!$C:$C," ") | CZ10: 刃 | DA10: =_xlfn.XLOOKUP(CZ10,対応表!$B:$B,対応表!$C:$C," ") | DB10: 列 | DC10: =_xlfn.XLOOKUP(DB10,対応表!$B:$B,対応表!$C:$C," ") | DD10: 别 | DE10: =_xlfn.XLOOKUP(DD10,対応表!$B:$B,対応表!$C:$C," ") -> ぶ | DF10: 刿 | DG10: =_xlfn.XLOOKUP(DF10,対応表!$B:$B,対応表!$C:$C," ") -> 花 | DH10: 剓 | DI10: =_xlfn.XLOOKUP(DH10,対応表!$B:$B,対応表!$C:$C," ") | DJ10: 剧 | DK10: =_xlfn.XLOOKUP(DJ10,対応表!$B:$B,対応表!$C:$C," ") | DL10: 剻 | DM10: =_xlfn.XLOOKUP(DL10,対応表!$B:$B,対応表!$C:$C," ") | DN10: 劏 | DO10: =_xlfn.XLOOKUP(DN10,対応表!$B:$B,対応表!$C:$C," ") -> ね | DP10: 劣 | DQ10: =_xlfn.XLOOKUP(DP10,対応表!$B:$B,対応表!$C:$C," ") | DR10: 劷 | DS10: =_xlfn.XLOOKUP(DR10,対応表!$B:$B,対応表!$C:$C," ") | DT10: 勋 | DU10: =_xlfn.XLOOKUP(DT10,対応表!$B:$B,対応表!$C:$C," ") | DV10: 募 | DW10: =_xlfn.XLOOKUP(DV10,対応表!$B:$B,対応表!$C:$C," ") | DX10: 勳 | DY10: =_xlfn.XLOOKUP(DX10,対応表!$B:$B,対応表!$C:$C," ") | DZ10: 匇 | EA10: =_xlfn.XLOOKUP(DZ10,対応表!$B:$B,対応表!$C:$C," ") -> 愛? | EB10: 匛 | EC10: =_xlfn.XLOOKUP(EB10,対応表!$B:$B,対応表!$C:$C," ") | ED10: 匯 | EE10: =_xlfn.XLOOKUP(ED10,対応表!$B:$B,対応表!$C:$C," ") | EF10: 千 | EG10: =_xlfn.XLOOKUP(EF10,対応表!$B:$B,対応表!$C:$C," ") | EH10: 南 | EI10: =_xlfn.XLOOKUP(EH10,対応表!$B:$B,対応表!$C:$C," ") | EJ10: 卫 | EK10: =_xlfn.XLOOKUP(EJ10,対応表!$B:$B,対応表!$C:$C," ")
A11: Ｉ | B11: 丈 | C11: =_xlfn.XLOOKUP(B11,対応表!$B:$B,対応表!$C:$C,"こ") -> こ | D11: 东 | E11: {=_xlfn.XLOOKUP(D11,対応表!$B:B,対応表!$C:C," ")} -> あ | F11: 丰 | G11: =_xlfn.XLOOKUP(F11,対応表!$B:$B,対応表!$C:$C," ") | H11: 乄 | I11: =_xlfn.XLOOKUP(H11,対応表!$B:$B,対応表!$C:$C," ") -> 常 | J11: 乘 | K11: =_xlfn.XLOOKUP(J11,対応表!$B:$B,対応表!$C:$C," ") | L11: 乬 | M11: =_xlfn.XLOOKUP(L11,対応表!$B:$B,対応表!$C:$C,"さ") -> さ | N11: 亀 | O11: =_xlfn.XLOOKUP(N11,対応表!$B:$B,対応表!$C:$C," ") | P11: 五 | Q11: =_xlfn.XLOOKUP(P11,対応表!$B:$B,対応表!$C:$C," ") -> 四? | R11: 亨 | S11: =_xlfn.XLOOKUP(R11,対応表!$B:$B,対応表!$C:$C," ") | T11: 亼 | U11: =_xlfn.XLOOKUP(T11,対応表!$B:$B,対応表!$C:$C," ") -> ぜ | V11: 仐 | W11: =_xlfn.XLOOKUP(V11,対応表!$B:$B,対応表!$C:$C," ") | X11: 令 | Y11: =_xlfn.XLOOKUP(X11,対応表!$B:$B,対応表!$C:$C," ") | Z11: 仸 | AA11: =_xlfn.XLOOKUP(Z11,対応表!$B:$B,対応表!$C:$C," ") | AB11: 伌 | AC11: =_xlfn.XLOOKUP(AB11,対応表!$B:$B,対応表!$C:$C," ") | AD11: 传 | AE11: =_xlfn.XLOOKUP(AD11,対応表!$B:$B,対応表!$C:$C," ") -> 早 | AF11: 伴 | AG11: =_xlfn.XLOOKUP(AF11,対応表!$B:$B,対応表!$C:$C," ") | AH11: 佈 | AI11: =_xlfn.XLOOKUP(AH11,対応表!$B:$B,対応表!$C:$C," ") | AJ11: 作 | AK11: =_xlfn.XLOOKUP(AJ11,対応表!$B:$B,対応表!$C:$C," ") | AL11: 佰 | AM11: =_xlfn.XLOOKUP(AL11,対応表!$B:$B,対応表!$C:$C,"っ") -> っ | AN11: 侄 | AO11: =_xlfn.XLOOKUP(AN11,対応表!$B:$B,対応表!$C:$C," ") | AP11: 侘 | AQ11: =_xlfn.XLOOKUP(AP11,対応表!$B:$B,対応表!$C:$C," ") | AR11: 侬 | AS11: =_xlfn.XLOOKUP(AR11,対応表!$B:$B,対応表!$C:$C," ") | AT11: 俀 | AU11: =_xlfn.XLOOKUP(AT11,対応表!$B:$B,対応表!$C:$C," ") | AV11: 俔 | AW11: =_xlfn.XLOOKUP(AV11,対応表!$B:$B,対応表!$C:$C," ") | AX11: 俨 | AY11: =_xlfn.XLOOKUP(AX11,対応表!$B:$B,対応表!$C:$C," ") | AZ11: 俼 | BA11: =_xlfn.XLOOKUP(AZ11,対応表!$B:$B,対応表!$C:$C," ") | BB11: 倐 | BC11: =_xlfn.XLOOKUP(BB11,対応表!$B:$B,対応表!$C:$C,"を") -> を | BD11: 値 | BE11: =_xlfn.XLOOKUP(BD11,対応表!$B:$B,対応表!$C:$C," ") | BF11: 倸 | BG11: =_xlfn.XLOOKUP(BF11,対応表!$B:$B,対応表!$C:$C," ") | BH11: 偌 | BI11: =_xlfn.XLOOKUP(BH11,対応表!$B:$B,対応表!$C:$C," ") | BJ11: 偠 | BK11: =_xlfn.XLOOKUP(BJ11,対応表!$B:$B,対応表!$C:$C," ") | BL11: 側 | BM11: =_xlfn.XLOOKUP(BL11,対応表!$B:$B,対応表!$C:$C," ") | BN11: 傈 | BO11: =_xlfn.XLOOKUP(BN11,対応表!$B:$B,対応表!$C:$C," ") | BP11: 傜 | BQ11: =_xlfn.XLOOKUP(BP11,対応表!$B:$B,対応表!$C:$C," ") | BR11: 傰 | BS11: =_xlfn.XLOOKUP(BR11,対応表!$B:$B,対応表!$C:$C," ") -> ぷ | BT11: 僄 | BU11: =_xlfn.XLOOKUP(BT11,対応表!$B:$B,対応表!$C:$C," ") | BV11: 僘 | BW11: =_xlfn.XLOOKUP(BV11,対応表!$B:$B,対応表!$C:$C," ") | BX11: 僬 | BY11: =_xlfn.XLOOKUP(BX11,対応表!$B:$B,対応表!$C:$C," ") | BZ11: 儀 | CA11: =_xlfn.XLOOKUP(BZ11,対応表!$B:$B,対応表!$C:$C," ") | CB11: 儔 | CC11: =_xlfn.XLOOKUP(CB11,対応表!$B:$B,対応表!$C:$C," ") | CD11: 儨 | CE11: =_xlfn.XLOOKUP(CD11,対応表!$B:$B,対応表!$C:$C," ") | CF11: 儼 | CG11: =_xlfn.XLOOKUP(CF11,対応表!$B:$B,対応表!$C:$C," ") -> 区 | CH11: 児 | CI11: =_xlfn.XLOOKUP(CH11,対応表!$B:$B,対応表!$C:$C," ") | CJ11: 兤 | CK11: =_xlfn.XLOOKUP(CJ11,対応表!$B:$B,対応表!$C:$C," ") | CL11: 典 | CM11: =_xlfn.XLOOKUP(CL11,対応表!$B:$B,対応表!$C:$C," ") | CN11: 册 | CO11: =_xlfn.XLOOKUP(CN11,対応表!$B:$B,対応表!$C:$C," ") | CP11: 冠 | CQ11: =_xlfn.XLOOKUP(CP11,対応表!$B:$B,対応表!$C:$C,"く") -> く | CR11: 冴 | CS11: =_xlfn.XLOOKUP(CR11,対応表!$B:$B,対応表!$C:$C," ") | CT11: 凈 | CU11: =_xlfn.XLOOKUP(CT11,対応表!$B:$B,対応表!$C:$C," ") | CV11: 凜 | CW11: =_xlfn.XLOOKUP(CV11,対応表!$B:$B,対応表!$C:$C," ") | CX11: 凰 | CY11: =_xlfn.XLOOKUP(CX11,対応表!$B:$B,対応表!$C:$C," ") | CZ11: 刄 | DA11: =_xlfn.XLOOKUP(CZ11,対応表!$B:$B,対応表!$C:$C," ") -> 録 | DB11: 刘 | DC11: =_xlfn.XLOOKUP(DB11,対応表!$B:$B,対応表!$C:$C," ") -> 時 | DD11: 刬 | DE11: =_xlfn.XLOOKUP(DD11,対応表!$B:$B,対応表!$C:$C," ") -> べ | DF11: 剀 | DG11: =_xlfn.XLOOKUP(DF11,対応表!$B:$B,対応表!$C:$C," ") | DH11: 剔 | DI11: =_xlfn.XLOOKUP(DH11,対応表!$B:$B,対応表!$C:$C," ") | DJ11: 剨 | DK11: =_xlfn.XLOOKUP(DJ11,対応表!$B:$B,対応表!$C:$C," ") | DL11: 剼 | DM11: =_xlfn.XLOOKUP(DL11,対応表!$B:$B,対応表!$C:$C," ") -> 集 | DN11: 劐 | DO11: =_xlfn.XLOOKUP(DN11,対応表!$B:$B,対応表!$C:$C," ") | DP11: 劤 | DQ11: =_xlfn.XLOOKUP(DP11,対応表!$B:$B,対応表!$C:$C," ") | DR11: 劸 | DS11: =_xlfn.XLOOKUP(DR11,対応表!$B:$B,対応表!$C:$C," ") | DT11: 勌 | DU11: =_xlfn.XLOOKUP(DT11,対応表!$B:$B,対応表!$C:$C," ") | DV11: 勠 | DW11: =_xlfn.XLOOKUP(DV11,対応表!$B:$B,対応表!$C:$C," ") | DX11: 勴 | DY11: =_xlfn.XLOOKUP(DX11,対応表!$B:$B,対応表!$C:$C," ") | DZ11: 匈 | EA11: =_xlfn.XLOOKUP(DZ11,対応表!$B:$B,対応表!$C:$C," ") | EB11: 匜 | EC11: =_xlfn.XLOOKUP(EB11,対応表!$B:$B,対応表!$C:$C," ") | ED11: 匰 | EE11: =_xlfn.XLOOKUP(ED11,対応表!$B:$B,対応表!$C:$C," ") -> 特? | EF11: 卄 | EG11: =_xlfn.XLOOKUP(EF11,対応表!$B:$B,対応表!$C:$C," ") | EH11: 単 | EI11: =_xlfn.XLOOKUP(EH11,対応表!$B:$B,対応表!$C:$C," ") | EJ11: 卬 | EK11: =_xlfn.XLOOKUP(EJ11,対応表!$B:$B,対応表!$C:$C," ")
A12: Ｊ | B12: 三 | C12: =_xlfn.XLOOKUP(B12,対応表!$B:$B,対応表!$C:$C," ") -> の | D12: 丝 | E12: {=_xlfn.XLOOKUP(D12,対応表!$B:B,対応表!$C:C," ")} -> り | F12: 丱 | G12: =_xlfn.XLOOKUP(F12,対応表!$B:$B,対応表!$C:$C," ") | H12: 久 | I12: =_xlfn.XLOOKUP(H12,対応表!$B:$B,対応表!$C:$C,"に") -> に | J12: 乙 | K12: =_xlfn.XLOOKUP(J12,対応表!$B:$B,対応表!$C:$C," ") | L12: 乭 | M12: =_xlfn.XLOOKUP(L12,対応表!$B:$B,対応表!$C:$C,"れ") -> れ | N12: 亁 | O12: =_xlfn.XLOOKUP(N12,対応表!$B:$B,対応表!$C:$C," ") | P12: 井 | Q12: =_xlfn.XLOOKUP(P12,対応表!$B:$B,対応表!$C:$C," ") | R12: 亩 | S12: =_xlfn.XLOOKUP(R12,対応表!$B:$B,対応表!$C:$C," ") -> ふ | T12: 亽 | U12: =_xlfn.XLOOKUP(T12,対応表!$B:$B,対応表!$C:$C," ") | V12: 仑 | W12: =_xlfn.XLOOKUP(V12,対応表!$B:$B,対応表!$C:$C," ") -> 異? | X12: 以 | Y12: =_xlfn.XLOOKUP(X12,対応表!$B:$B,対応表!$C:$C," ") | Z12: 仹 | AA12: =_xlfn.XLOOKUP(Z12,対応表!$B:$B,対応表!$C:$C," ") | AB12: 伍 | AC12: =_xlfn.XLOOKUP(AB12,対応表!$B:$B,対応表!$C:$C," ") | AD12: 伡 | AE12: =_xlfn.XLOOKUP(AD12,対応表!$B:$B,対応表!$C:$C," ") | AF12: 伵 | AG12: =_xlfn.XLOOKUP(AF12,対応表!$B:$B,対応表!$C:$C," ") | AH12: 佉 | AI12: =_xlfn.XLOOKUP(AH12,対応表!$B:$B,対応表!$C:$C," ") | AJ12: 佝 | AK12: =_xlfn.XLOOKUP(AJ12,対応表!$B:$B,対応表!$C:$C," ") | AL12: 佱 | AM12: =_xlfn.XLOOKUP(AL12,対応表!$B:$B,対応表!$C:$C,"て") -> て | AN12: 侅 | AO12: =_xlfn.XLOOKUP(AN12,対応表!$B:$B,対応表!$C:$C," ") | AP12: 侙 | AQ12: =_xlfn.XLOOKUP(AP12,対応表!$B:$B,対応表!$C:$C," ") | AR12: 侭 | AS12: =_xlfn.XLOOKUP(AR12,対応表!$B:$B,対応表!$C:$C," ") | AT12: 俁 | AU12: =_xlfn.XLOOKUP(AT12,対応表!$B:$B,対応表!$C:$C," ") | AV12: 俕 | AW12: =_xlfn.XLOOKUP(AV12,対応表!$B:$B,対応表!$C:$C," ") | AX12: 俩 | AY12: =_xlfn.XLOOKUP(AX12,対応表!$B:$B,対応表!$C:$C," ") | AZ12: 俽 | BA12: =_xlfn.XLOOKUP(AZ12,対応表!$B:$B,対応表!$C:$C," ") | BB12: 們 | BC12: =_xlfn.XLOOKUP(BB12,対応表!$B:$B,対応表!$C:$C," ") -> 見 | BD12: 倥 | BE12: =_xlfn.XLOOKUP(BD12,対応表!$B:$B,対応表!$C:$C," ") | BF12: 倹 | BG12: =_xlfn.XLOOKUP(BF12,対応表!$B:$B,対応表!$C:$C," ") | BH12: 偍 | BI12: =_xlfn.XLOOKUP(BH12,対応表!$B:$B,対応表!$C:$C," ") | BJ12: 偡 | BK12: =_xlfn.XLOOKUP(BJ12,対応表!$B:$B,対応表!$C:$C," ") | BL12: 偵 | BM12: =_xlfn.XLOOKUP(BL12,対応表!$B:$B,対応表!$C:$C," ") | BN12: 傉 | BO12: =_xlfn.XLOOKUP(BN12,対応表!$B:$B,対応表!$C:$C," ") | BP12: 傝 | BQ12: =_xlfn.XLOOKUP(BP12,対応表!$B:$B,対応表!$C:$C," ") | BR12: 傱 | BS12: =_xlfn.XLOOKUP(BR12,対応表!$B:$B,対応表!$C:$C," ") | BT12: 僅 | BU12: =_xlfn.XLOOKUP(BT12,対応表!$B:$B,対応表!$C:$C," ") | BV12: 僙 | BW12: =_xlfn.XLOOKUP(BV12,対応表!$B:$B,対応表!$C:$C," ") | BX12: 僭 | BY12: =_xlfn.XLOOKUP(BX12,対応表!$B:$B,対応表!$C:$C," ") -> 最 | BZ12: 儁 | CA12: =_xlfn.XLOOKUP(BZ12,対応表!$B:$B,対応表!$C:$C," ") | CB12: 儕 | CC12: =_xlfn.XLOOKUP(CB12,対応表!$B:$B,対応表!$C:$C," ") | CD12: 儩 | CE12: =_xlfn.XLOOKUP(CD12,対応表!$B:$B,対応表!$C:$C," ") | CF12: 儽 | CG12: =_xlfn.XLOOKUP(CF12,対応表!$B:$B,対応表!$C:$C," ") -> 別? | CH12: 兑 | CI12: =_xlfn.XLOOKUP(CH12,対応表!$B:$B,対応表!$C:$C," ") | CJ12: 入 | CK12: =_xlfn.XLOOKUP(CJ12,対応表!$B:$B,対応表!$C:$C," ") | CL12: 兹 | CM12: =_xlfn.XLOOKUP(CL12,対応表!$B:$B,対応表!$C:$C," ") | CN12: 再 | CO12: =_xlfn.XLOOKUP(CN12,対応表!$B:$B,対応表!$C:$C," ") | CP12: 冡 | CQ12: =_xlfn.XLOOKUP(CP12,対応表!$B:$B,対応表!$C:$C," ") -> 命 | CR12: 况 | CS12: =_xlfn.XLOOKUP(CR12,対応表!$B:$B,対応表!$C:$C," ") | CT12: 凉 | CU12: =_xlfn.XLOOKUP(CT12,対応表!$B:$B,対応表!$C:$C," ") | CV12: 凝 | CW12: =_xlfn.XLOOKUP(CV12,対応表!$B:$B,対応表!$C:$C," ") | CX12: 凱 | CY12: =_xlfn.XLOOKUP(CX12,対応表!$B:$B,対応表!$C:$C," ") | CZ12: 刅 | DA12: =_xlfn.XLOOKUP(CZ12,対応表!$B:$B,対応表!$C:$C," ") | DB12: 则 | DC12: =_xlfn.XLOOKUP(DB12,対応表!$B:$B,対応表!$C:$C," ") | DD12: 刭 | DE12: =_xlfn.XLOOKUP(DD12,対応表!$B:$B,対応表!$C:$C," ") | DF12: 剁 | DG12: =_xlfn.XLOOKUP(DF12,対応表!$B:$B,対応表!$C:$C," ") | DH12: 剕 | DI12: =_xlfn.XLOOKUP(DH12,対応表!$B:$B,対応表!$C:$C," ") | DJ12: 剩 | DK12: =_xlfn.XLOOKUP(DJ12,対応表!$B:$B,対応表!$C:$C," ") | DL12: 剽 | DM12: =_xlfn.XLOOKUP(DL12,対応表!$B:$B,対応表!$C:$C," ") | DN12: 劑 | DO12: =_xlfn.XLOOKUP(DN12,対応表!$B:$B,対応表!$C:$C," ") | DP12: 劥 | DQ12: =_xlfn.XLOOKUP(DP12,対応表!$B:$B,対応表!$C:$C," ") | DR12: 効 | DS12: =_xlfn.XLOOKUP(DR12,対応表!$B:$B,対応表!$C:$C," ") | DT12: 勍 | DU12: =_xlfn.XLOOKUP(DT12,対応表!$B:$B,対応表!$C:$C," ") -> 思 | DV12: 勡 | DW12: =_xlfn.XLOOKUP(DV12,対応表!$B:$B,対応表!$C:$C," ") | DX12: 勵 | DY12: =_xlfn.XLOOKUP(DX12,対応表!$B:$B,対応表!$C:$C," ") -> 限? | DZ12: 匉 | EA12: =_xlfn.XLOOKUP(DZ12,対応表!$B:$B,対応表!$C:$C," ") | EB12: 匝 | EC12: =_xlfn.XLOOKUP(EB12,対応表!$B:$B,対応表!$C:$C," ") | ED12: 匱 | EE12: =_xlfn.XLOOKUP(ED12,対応表!$B:$B,対応表!$C:$C," ") | EF12: 卅 | EG12: =_xlfn.XLOOKUP(EF12,対応表!$B:$B,対応表!$C:$C," ") | EH12: 卙 | EI12: =_xlfn.XLOOKUP(EH12,対応表!$B:$B,対応表!$C:$C," ") | EJ12: 卭 | EK12: =_xlfn.XLOOKUP(EJ12,対応表!$B:$B,対応表!$C:$C," ")
A13: Ｋ | B13: 上 | C13: =_xlfn.XLOOKUP(B13,対応表!$B:$B,対応表!$C:$C,"不") -> 不 | D13: 丞 | E13: {=_xlfn.XLOOKUP(D13,対応表!$B:B,対応表!$C:C," ")} -> 受 | F13: 串 | G13: =_xlfn.XLOOKUP(F13,対応表!$B:$B,対応表!$C:$C," ") | H13: 乆 | I13: =_xlfn.XLOOKUP(H13,対応表!$B:$B,対応表!$C:$C," ") -> 深? | J13: 乚 | K13: =_xlfn.XLOOKUP(J13,対応表!$B:$B,対応表!$C:$C," ") | L13: 乮 | M13: =_xlfn.XLOOKUP(L13,対応表!$B:$B,対応表!$C:$C,"た") -> た | N13: 亂 | O13: =_xlfn.XLOOKUP(N13,対応表!$B:$B,対応表!$C:$C," ") | P13: 亖 | Q13: =_xlfn.XLOOKUP(P13,対応表!$B:$B,対応表!$C:$C," ") | R13: 亪 | S13: =_xlfn.XLOOKUP(R13,対応表!$B:$B,対応表!$C:$C," ") | T13: 亾 | U13: =_xlfn.XLOOKUP(T13,対応表!$B:$B,対応表!$C:$C," ") -> 防? | V13: 仒 | W13: =_xlfn.XLOOKUP(V13,対応表!$B:$B,対応表!$C:$C," ") -> 形 | X13: 仦 | Y13: =_xlfn.XLOOKUP(X13,対応表!$B:$B,対応表!$C:$C," ") | Z13: 仺 | AA13: =_xlfn.XLOOKUP(Z13,対応表!$B:$B,対応表!$C:$C," ") | AB13: 伎 | AC13: =_xlfn.XLOOKUP(AB13,対応表!$B:$B,対応表!$C:$C," ") | AD13: 伢 | AE13: =_xlfn.XLOOKUP(AD13,対応表!$B:$B,対応表!$C:$C," ") | AF13: 伶 | AG13: =_xlfn.XLOOKUP(AF13,対応表!$B:$B,対応表!$C:$C," ") | AH13: 佊 | AI13: =_xlfn.XLOOKUP(AH13,対応表!$B:$B,対応表!$C:$C," ") | AJ13: 佞 | AK13: =_xlfn.XLOOKUP(AJ13,対応表!$B:$B,対応表!$C:$C," ") | AL13: 佲 | AM13: =_xlfn.XLOOKUP(AL13,対応表!$B:$B,対応表!$C:$C," ") -> 食 | AN13: 來 | AO13: =_xlfn.XLOOKUP(AN13,対応表!$B:$B,対応表!$C:$C," ") | AP13: 侚 | AQ13: =_xlfn.XLOOKUP(AP13,対応表!$B:$B,対応表!$C:$C," ") -> 越? | AR13: 侮 | AS13: =_xlfn.XLOOKUP(AR13,対応表!$B:$B,対応表!$C:$C," ") | AT13: 係 | AU13: =_xlfn.XLOOKUP(AT13,対応表!$B:$B,対応表!$C:$C," ") -> 込 | AV13: 俖 | AW13: =_xlfn.XLOOKUP(AV13,対応表!$B:$B,対応表!$C:$C," ") | AX13: 俪 | AY13: =_xlfn.XLOOKUP(AX13,対応表!$B:$B,対応表!$C:$C," ") | AZ13: 俾 | BA13: =_xlfn.XLOOKUP(AZ13,対応表!$B:$B,対応表!$C:$C," ") | BB13: 倒 | BC13: =_xlfn.XLOOKUP(BB13,対応表!$B:$B,対応表!$C:$C," ") | BD13: 倦 | BE13: =_xlfn.XLOOKUP(BD13,対応表!$B:$B,対応表!$C:$C," ") | BF13: 债 | BG13: =_xlfn.XLOOKUP(BF13,対応表!$B:$B,対応表!$C:$C," ") | BH13: 偎 | BI13: =_xlfn.XLOOKUP(BH13,対応表!$B:$B,対応表!$C:$C," ") | BJ13: 偢 | BK13: =_xlfn.XLOOKUP(BJ13,対応表!$B:$B,対応表!$C:$C," ") -> 多 | BL13: 偶 | BM13: =_xlfn.XLOOKUP(BL13,対応表!$B:$B,対応表!$C:$C," ") | BN13: 傊 | BO13: =_xlfn.XLOOKUP(BN13,対応表!$B:$B,対応表!$C:$C," ") | BP13: 傞 | BQ13: =_xlfn.XLOOKUP(BP13,対応表!$B:$B,対応表!$C:$C," ") | BR13: 傲 | BS13: =_xlfn.XLOOKUP(BR13,対応表!$B:$B,対応表!$C:$C," ") | BT13: 僆 | BU13: =_xlfn.XLOOKUP(BT13,対応表!$B:$B,対応表!$C:$C," ") | BV13: 僚 | BW13: =_xlfn.XLOOKUP(BV13,対応表!$B:$B,対応表!$C:$C," ") -> 同? | BX13: 僮 | BY13: =_xlfn.XLOOKUP(BX13,対応表!$B:$B,対応表!$C:$C," ") -> 中 | BZ13: 儂 | CA13: =_xlfn.XLOOKUP(BZ13,対応表!$B:$B,対応表!$C:$C," ") | CB13: 儖 | CC13: =_xlfn.XLOOKUP(CB13,対応表!$B:$B,対応表!$C:$C," ") | CD13: 優 | CE13: =_xlfn.XLOOKUP(CD13,対応表!$B:$B,対応表!$C:$C," ") | CF13: 儾 | CG13: =_xlfn.XLOOKUP(CF13,対応表!$B:$B,対応表!$C:$C,"が") -> が | CH13: 兒 | CI13: =_xlfn.XLOOKUP(CH13,対応表!$B:$B,対応表!$C:$C," ") | CJ13: 兦 | CK13: =_xlfn.XLOOKUP(CJ13,対応表!$B:$B,対応表!$C:$C," ") | CL13: 兺 | CM13: =_xlfn.XLOOKUP(CL13,対応表!$B:$B,対応表!$C:$C," ") | CN13: 冎 | CO13: =_xlfn.XLOOKUP(CN13,対応表!$B:$B,対応表!$C:$C," ") | CP13: 冢 | CQ13: =_xlfn.XLOOKUP(CP13,対応表!$B:$B,対応表!$C:$C,"を") -> を | CR13: 冶 | CS13: =_xlfn.XLOOKUP(CR13,対応表!$B:$B,対応表!$C:$C," ") | CT13: 凊 | CU13: =_xlfn.XLOOKUP(CT13,対応表!$B:$B,対応表!$C:$C," ") | CV13: 凞 | CW13: =_xlfn.XLOOKUP(CV13,対応表!$B:$B,対応表!$C:$C," ") | CX13: 凲 | CY13: =_xlfn.XLOOKUP(CX13,対応表!$B:$B,対応表!$C:$C," ") | CZ13: 分 | DA13: =_xlfn.XLOOKUP(CZ13,対応表!$B:$B,対応表!$C:$C," ") | DB13: 刚 | DC13: =_xlfn.XLOOKUP(DB13,対応表!$B:$B,対応表!$C:$C," ") | DD13: 刮 | DE13: =_xlfn.XLOOKUP(DD13,対応表!$B:$B,対応表!$C:$C," ") | DF13: 剂 | DG13: =_xlfn.XLOOKUP(DF13,対応表!$B:$B,対応表!$C:$C," ") | DH13: 剖 | DI13: =_xlfn.XLOOKUP(DH13,対応表!$B:$B,対応表!$C:$C," ") | DJ13: 剪 | DK13: =_xlfn.XLOOKUP(DJ13,対応表!$B:$B,対応表!$C:$C," ") -> 子 | DL13: 剾 | DM13: =_xlfn.XLOOKUP(DL13,対応表!$B:$B,対応表!$C:$C," ") | DN13: 劒 | DO13: =_xlfn.XLOOKUP(DN13,対応表!$B:$B,対応表!$C:$C," ") | DP13: 劦 | DQ13: =_xlfn.XLOOKUP(DP13,対応表!$B:$B,対応表!$C:$C," ") | DR13: 劺 | DS13: =_xlfn.XLOOKUP(DR13,対応表!$B:$B,対応表!$C:$C," ") | DT13: 勎 | DU13: =_xlfn.XLOOKUP(DT13,対応表!$B:$B,対応表!$C:$C," ") | DV13: 勢 | DW13: =_xlfn.XLOOKUP(DV13,対応表!$B:$B,対応表!$C:$C," ") -> 兆? | DX13: 勶 | DY13: =_xlfn.XLOOKUP(DX13,対応表!$B:$B,対応表!$C:$C," ") | DZ13: 匊 | EA13: =_xlfn.XLOOKUP(DZ13,対応表!$B:$B,対応表!$C:$C," ") | EB13: 匞 | EC13: =_xlfn.XLOOKUP(EB13,対応表!$B:$B,対応表!$C:$C," ") | ED13: 匲 | EE13: =_xlfn.XLOOKUP(ED13,対応表!$B:$B,対応表!$C:$C," ") | EF13: 卆 | EG13: =_xlfn.XLOOKUP(EF13,対応表!$B:$B,対応表!$C:$C," ") | EH13: 博 | EI13: =_xlfn.XLOOKUP(EH13,対応表!$B:$B,対応表!$C:$C," ") | EJ13: 卮 | EK13: =_xlfn.XLOOKUP(EJ13,対応表!$B:$B,対応表!$C:$C," ")
A14: Ｌ | B14: 下 | C14: =_xlfn.XLOOKUP(B14,対応表!$B:$B,対応表!$C:$C," ") -> 確? | D14: 丟 | E14: {=_xlfn.XLOOKUP(D14,対応表!$B:B,対応表!$C:C," ")} -> け | F14: 丳 | G14: =_xlfn.XLOOKUP(F14,対応表!$B:$B,対応表!$C:$C," ") | H14: 乇 | I14: =_xlfn.XLOOKUP(H14,対応表!$B:$B,対応表!$C:$C," ") -> く | J14: 乛 | K14: =_xlfn.XLOOKUP(J14,対応表!$B:$B,対応表!$C:$C," ") -> と | L14: 乯 | M14: =_xlfn.XLOOKUP(L14,対応表!$B:$B,対応表!$C:$C," ") -> だ | N14: 亃 | O14: =_xlfn.XLOOKUP(N14,対応表!$B:$B,対応表!$C:$C," ") -> そ | P14: 亗 | Q14: =_xlfn.XLOOKUP(P14,対応表!$B:$B,対応表!$C:$C," ") | R14: 享 | S14: =_xlfn.XLOOKUP(R14,対応表!$B:$B,対応表!$C:$C," ") | T14: 亿 | U14: =_xlfn.XLOOKUP(T14,対応表!$B:$B,対応表!$C:$C," ") | V14: 仓 | W14: =_xlfn.XLOOKUP(V14,対応表!$B:$B,対応表!$C:$C," ") | X14: 仧 | Y14: =_xlfn.XLOOKUP(X14,対応表!$B:$B,対応表!$C:$C," ") | Z14: 任 | AA14: =_xlfn.XLOOKUP(Z14,対応表!$B:$B,対応表!$C:$C," ") | AB14: 伏 | AC14: =_xlfn.XLOOKUP(AB14,対応表!$B:$B,対応表!$C:$C," ") -> 街 | AD14: 伣 | AE14: =_xlfn.XLOOKUP(AD14,対応表!$B:$B,対応表!$C:$C," ") | AF14: 伷 | AG14: =_xlfn.XLOOKUP(AF14,対応表!$B:$B,対応表!$C:$C," ") | AH14: 佋 | AI14: =_xlfn.XLOOKUP(AH14,対応表!$B:$B,対応表!$C:$C," ") -> 自 | AJ14: 佟 | AK14: =_xlfn.XLOOKUP(AJ14,対応表!$B:$B,対応表!$C:$C," ") -> 空 | AL14: 佳 | AM14: =_xlfn.XLOOKUP(AL14,対応表!$B:$B,対応表!$C:$C," ") -> 事 | AN14: 侇 | AO14: =_xlfn.XLOOKUP(AN14,対応表!$B:$B,対応表!$C:$C," ") | AP14: 供 | AQ14: =_xlfn.XLOOKUP(AP14,対応表!$B:$B,対応表!$C:$C," ") | AR14: 侯 | AS14: =_xlfn.XLOOKUP(AR14,対応表!$B:$B,対応表!$C:$C," ") | AT14: 促 | AU14: =_xlfn.XLOOKUP(AT14,対応表!$B:$B,対応表!$C:$C," ") | AV14: 俗 | AW14: =_xlfn.XLOOKUP(AV14,対応表!$B:$B,対応表!$C:$C," ") | AX14: 俫 | AY14: =_xlfn.XLOOKUP(AX14,対応表!$B:$B,対応表!$C:$C," ") | AZ14: 俿 | BA14: =_xlfn.XLOOKUP(AZ14,対応表!$B:$B,対応表!$C:$C," ") | BB14: 倓 | BC14: =_xlfn.XLOOKUP(BB14,対応表!$B:$B,対応表!$C:$C," ") | BD14: 倧 | BE14: =_xlfn.XLOOKUP(BD14,対応表!$B:$B,対応表!$C:$C," ") | BF14: 倻 | BG14: =_xlfn.XLOOKUP(BF14,対応表!$B:$B,対応表!$C:$C," ") | BH14: 偏 | BI14: =_xlfn.XLOOKUP(BH14,対応表!$B:$B,対応表!$C:$C," ") | BJ14: 偣 | BK14: =_xlfn.XLOOKUP(BJ14,対応表!$B:$B,対応表!$C:$C," ") | BL14: 偷 | BM14: =_xlfn.XLOOKUP(BL14,対応表!$B:$B,対応表!$C:$C," ") | BN14: 傋 | BO14: =_xlfn.XLOOKUP(BN14,対応表!$B:$B,対応表!$C:$C," ") | BP14: 傟 | BQ14: =_xlfn.XLOOKUP(BP14,対応表!$B:$B,対応表!$C:$C," ") -> 相 | BR14: 傳 | BS14: =_xlfn.XLOOKUP(BR14,対応表!$B:$B,対応表!$C:$C," ") | BT14: 僇 | BU14: =_xlfn.XLOOKUP(BT14,対応表!$B:$B,対応表!$C:$C," ") | BV14: 僛 | BW14: =_xlfn.XLOOKUP(BV14,対応表!$B:$B,対応表!$C:$C," ") | BX14: 僯 | BY14: =_xlfn.XLOOKUP(BX14,対応表!$B:$B,対応表!$C:$C," ") | BZ14: 儃 | CA14: =_xlfn.XLOOKUP(BZ14,対応表!$B:$B,対応表!$C:$C," ") | CB14: 儗 | CC14: =_xlfn.XLOOKUP(CB14,対応表!$B:$B,対応表!$C:$C," ") | CD14: 儫 | CE14: =_xlfn.XLOOKUP(CD14,対応表!$B:$B,対応表!$C:$C," ") | CF14: 儿 | CG14: =_xlfn.XLOOKUP(CF14,対応表!$B:$B,対応表!$C:$C," ") -> 存 | CH14: 兓 | CI14: =_xlfn.XLOOKUP(CH14,対応表!$B:$B,対応表!$C:$C," ") | CJ14: 內 | CK14: =_xlfn.XLOOKUP(CJ14,対応表!$B:$B,対応表!$C:$C," ") | CL14: 养 | CM14: =_xlfn.XLOOKUP(CL14,対応表!$B:$B,対応表!$C:$C," ") | CN14: 冏 | CO14: =_xlfn.XLOOKUP(CN14,対応表!$B:$B,対応表!$C:$C," ") | CP14: 冣 | CQ14: =_xlfn.XLOOKUP(CP14,対応表!$B:$B,対応表!$C:$C," ") -> 大 | CR14: 冷 | CS14: =_xlfn.XLOOKUP(CR14,対応表!$B:$B,対応表!$C:$C," ") | CT14: 凋 | CU14: =_xlfn.XLOOKUP(CT14,対応表!$B:$B,対応表!$C:$C," ") -> ぴ | CV14: 凟 | CW14: =_xlfn.XLOOKUP(CV14,対応表!$B:$B,対応表!$C:$C," ") | CX14: 凳 | CY14: =_xlfn.XLOOKUP(CX14,対応表!$B:$B,対応表!$C:$C," ") -> 続 | CZ14: 切 | DA14: =_xlfn.XLOOKUP(CZ14,対応表!$B:$B,対応表!$C:$C," ") | DB14: 创 | DC14: =_xlfn.XLOOKUP(DB14,対応表!$B:$B,対応表!$C:$C," ") | DD14: 刯 | DE14: =_xlfn.XLOOKUP(DD14,対応表!$B:$B,対応表!$C:$C," ") | DF14: 剃 | DG14: =_xlfn.XLOOKUP(DF14,対応表!$B:$B,対応表!$C:$C," ") -> 清 | DH14: 剗 | DI14: =_xlfn.XLOOKUP(DH14,対応表!$B:$B,対応表!$C:$C," ") | DJ14: 剫 | DK14: =_xlfn.XLOOKUP(DJ14,対応表!$B:$B,対応表!$C:$C," ") | DL14: 剿 | DM14: =_xlfn.XLOOKUP(DL14,対応表!$B:$B,対応表!$C:$C," ") | DN14: 劓 | DO14: =_xlfn.XLOOKUP(DN14,対応表!$B:$B,対応表!$C:$C," ") | DP14: 劧 | DQ14: =_xlfn.XLOOKUP(DP14,対応表!$B:$B,対応表!$C:$C," ") | DR14: 劻 | DS14: =_xlfn.XLOOKUP(DR14,対応表!$B:$B,対応表!$C:$C," ") | DT14: 勏 | DU14: =_xlfn.XLOOKUP(DT14,対応表!$B:$B,対応表!$C:$C," ") | DV14: 勣 | DW14: =_xlfn.XLOOKUP(DV14,対応表!$B:$B,対応表!$C:$C," ") | DX14: 勷 | DY14: =_xlfn.XLOOKUP(DX14,対応表!$B:$B,対応表!$C:$C," ") | DZ14: 匋 | EA14: =_xlfn.XLOOKUP(DZ14,対応表!$B:$B,対応表!$C:$C," ") | EB14: 匟 | EC14: =_xlfn.XLOOKUP(EB14,対応表!$B:$B,対応表!$C:$C," ") | ED14: 匳 | EE14: =_xlfn.XLOOKUP(ED14,対応表!$B:$B,対応表!$C:$C," ") | EF14: 升 | EG14: =_xlfn.XLOOKUP(EF14,対応表!$B:$B,対応表!$C:$C," ") | EH14: 卛 | EI14: =_xlfn.XLOOKUP(EH14,対応表!$B:$B,対応表!$C:$C," ") | EJ14: 卯 | EK14: =_xlfn.XLOOKUP(EJ14,対応表!$B:$B,対応表!$C:$C," ")
A15: Ｍ | B15: 丌 | C15: =_xlfn.XLOOKUP(B15,対応表!$B:$B,対応表!$C:$C," ") -> か | D15: 丠 | E15: {=_xlfn.XLOOKUP(D15,対応表!$B:B,対応表!$C:C,"継")} -> 継? | F15: 临 | G15: =_xlfn.XLOOKUP(F15,対応表!$B:$B,対応表!$C:$C," ") -> ほ | H15: 么 | I15: =_xlfn.XLOOKUP(H15,対応表!$B:$B,対応表!$C:$C," ") | J15: 乜 | K15: =_xlfn.XLOOKUP(J15,対応表!$B:$B,対応表!$C:$C," ") | L15: 买 | M15: =_xlfn.XLOOKUP(L15,対応表!$B:$B,対応表!$C:$C," ") -> ろ | N15: 亄 | O15: =_xlfn.XLOOKUP(N15,対応表!$B:$B,対応表!$C:$C," ") | P15: 亘 | Q15: =_xlfn.XLOOKUP(P15,対応表!$B:$B,対応表!$C:$C," ") -> [亘]? | R15: 京 | S15: =_xlfn.XLOOKUP(R15,対応表!$B:$B,対応表!$C:$C," ") | T15: 什 | U15: =_xlfn.XLOOKUP(T15,対応表!$B:$B,対応表!$C:$C," ") -> 地 | V15: 仔 | W15: =_xlfn.XLOOKUP(V15,対応表!$B:$B,対応表!$C:$C," ") | X15: 仨 | Y15: =_xlfn.XLOOKUP(X15,対応表!$B:$B,対応表!$C:$C," ") | Z15: 仼 | AA15: =_xlfn.XLOOKUP(Z15,対応表!$B:$B,対応表!$C:$C," ") | AB15: 伐 | AC15: =_xlfn.XLOOKUP(AB15,対応表!$B:$B,対応表!$C:$C," ") | AD15: 伤 | AE15: =_xlfn.XLOOKUP(AD15,対応表!$B:$B,対応表!$C:$C," ") | AF15: 伸 | AG15: =_xlfn.XLOOKUP(AF15,対応表!$B:$B,対応表!$C:$C," ") -> て | AH15: 佌 | AI15: =_xlfn.XLOOKUP(AH15,対応表!$B:$B,対応表!$C:$C," ") | AJ15: 你 | AK15: =_xlfn.XLOOKUP(AJ15,対応表!$B:$B,対応表!$C:$C," ") | AL15: 佴 | AM15: =_xlfn.XLOOKUP(AL15,対応表!$B:$B,対応表!$C:$C," ") | AN15: 侈 | AO15: =_xlfn.XLOOKUP(AN15,対応表!$B:$B,対応表!$C:$C," ") | AP15: 侜 | AQ15: =_xlfn.XLOOKUP(AP15,対応表!$B:$B,対応表!$C:$C," ") | AR15: 侰 | AS15: =_xlfn.XLOOKUP(AR15,対応表!$B:$B,対応表!$C:$C," ") | AT15: 俄 | AU15: =_xlfn.XLOOKUP(AT15,対応表!$B:$B,対応表!$C:$C," ") | AV15: 俘 | AW15: =_xlfn.XLOOKUP(AV15,対応表!$B:$B,対応表!$C:$C," ") | AX15: 俬 | AY15: =_xlfn.XLOOKUP(AX15,対応表!$B:$B,対応表!$C:$C," ") -> ゃ | AZ15: 倀 | BA15: =_xlfn.XLOOKUP(AZ15,対応表!$B:$B,対応表!$C:$C," ") | BB15: 倔 | BC15: =_xlfn.XLOOKUP(BB15,対応表!$B:$B,対応表!$C:$C," ") | BD15: 倨 | BE15: =_xlfn.XLOOKUP(BD15,対応表!$B:$B,対応表!$C:$C," ") -> ぺ | BF15: 值 | BG15: =_xlfn.XLOOKUP(BF15,対応表!$B:$B,対応表!$C:$C," ") | BH15: 偐 | BI15: =_xlfn.XLOOKUP(BH15,対応表!$B:$B,対応表!$C:$C," ") | BJ15: 偤 | BK15: =_xlfn.XLOOKUP(BJ15,対応表!$B:$B,対応表!$C:$C," ") | BL15: 偸 | BM15: =_xlfn.XLOOKUP(BL15,対応表!$B:$B,対応表!$C:$C," ") | BN15: 傌 | BO15: =_xlfn.XLOOKUP(BN15,対応表!$B:$B,対応表!$C:$C," ") | BP15: 傠 | BQ15: =_xlfn.XLOOKUP(BP15,対応表!$B:$B,対応表!$C:$C," ") -> 手 | BR15: 傴 | BS15: =_xlfn.XLOOKUP(BR15,対応表!$B:$B,対応表!$C:$C," ") | BT15: 僈 | BU15: =_xlfn.XLOOKUP(BT15,対応表!$B:$B,対応表!$C:$C," ") | BV15: 僜 | BW15: =_xlfn.XLOOKUP(BV15,対応表!$B:$B,対応表!$C:$C," ") | BX15: 僰 | BY15: =_xlfn.XLOOKUP(BX15,対応表!$B:$B,対応表!$C:$C," ") | BZ15: 億 | CA15: =_xlfn.XLOOKUP(BZ15,対応表!$B:$B,対応表!$C:$C," ") | CB15: 儘 | CC15: =_xlfn.XLOOKUP(CB15,対応表!$B:$B,対応表!$C:$C," ") | CD15: 儬 | CE15: =_xlfn.XLOOKUP(CD15,対応表!$B:$B,対応表!$C:$C," ") | CF15: 兀 | CG15: =_xlfn.XLOOKUP(CF15,対応表!$B:$B,対応表!$C:$C,"在") -> 在 | CH15: 兔 | CI15: =_xlfn.XLOOKUP(CH15,対応表!$B:$B,対応表!$C:$C," ") | CJ15: 全 | CK15: =_xlfn.XLOOKUP(CJ15,対応表!$B:$B,対応表!$C:$C," ") | CL15: 兼 | CM15: =_xlfn.XLOOKUP(CL15,対応表!$B:$B,対応表!$C:$C," ") | CN15: 冐 | CO15: =_xlfn.XLOOKUP(CN15,対応表!$B:$B,対応表!$C:$C," ") | CP15: 冤 | CQ15: =_xlfn.XLOOKUP(CP15,対応表!$B:$B,対応表!$C:$C," ") -> 切 | CR15: 冸 | CS15: =_xlfn.XLOOKUP(CR15,対応表!$B:$B,対応表!$C:$C," ") | CT15: 凌 | CU15: =_xlfn.XLOOKUP(CT15,対応表!$B:$B,対応表!$C:$C," ") | CV15: 几 | CW15: =_xlfn.XLOOKUP(CV15,対応表!$B:$B,対応表!$C:$C," ") | CX15: 凴 | CY15: =_xlfn.XLOOKUP(CX15,対応表!$B:$B,対応表!$C:$C," ") | CZ15: 刈 | DA15: =_xlfn.XLOOKUP(CZ15,対応表!$B:$B,対応表!$C:$C," ") | DB15: 刜 | DC15: =_xlfn.XLOOKUP(DB15,対応表!$B:$B,対応表!$C:$C," ") | DD15: 到 | DE15: =_xlfn.XLOOKUP(DD15,対応表!$B:$B,対応表!$C:$C," ") | DF15: 剄 | DG15: =_xlfn.XLOOKUP(DF15,対応表!$B:$B,対応表!$C:$C," ") | DH15: 剘 | DI15: =_xlfn.XLOOKUP(DH15,対応表!$B:$B,対応表!$C:$C," ") | DJ15: 剬 | DK15: =_xlfn.XLOOKUP(DJ15,対応表!$B:$B,対応表!$C:$C," ") -> 初 | DL15: 劀 | DM15: =_xlfn.XLOOKUP(DL15,対応表!$B:$B,対応表!$C:$C," ") | DN15: 劔 | DO15: =_xlfn.XLOOKUP(DN15,対応表!$B:$B,対応表!$C:$C," ") | DP15: 动 | DQ15: =_xlfn.XLOOKUP(DP15,対応表!$B:$B,対応表!$C:$C," ") | DR15: 劼 | DS15: =_xlfn.XLOOKUP(DR15,対応表!$B:$B,対応表!$C:$C," ") | DT15: 勐 | DU15: =_xlfn.XLOOKUP(DT15,対応表!$B:$B,対応表!$C:$C," ") | DV15: 勤 | DW15: =_xlfn.XLOOKUP(DV15,対応表!$B:$B,対応表!$C:$C," ") | DX15: 勸 | DY15: =_xlfn.XLOOKUP(DX15,対応表!$B:$B,対応表!$C:$C," ") | DZ15: 匌 | EA15: =_xlfn.XLOOKUP(DZ15,対応表!$B:$B,対応表!$C:$C," ") | EB15: 匠 | EC15: =_xlfn.XLOOKUP(EB15,対応表!$B:$B,対応表!$C:$C," ") | ED15: 匴 | EE15: =_xlfn.XLOOKUP(ED15,対応表!$B:$B,対応表!$C:$C," ") | EF15: 午 | EG15: =_xlfn.XLOOKUP(EF15,対応表!$B:$B,対応表!$C:$C," ") | EH15: 卜 | EI15: =_xlfn.XLOOKUP(EH15,対応表!$B:$B,対応表!$C:$C," ") | EJ15: 印 | EK15: =_xlfn.XLOOKUP(EJ15,対応表!$B:$B,対応表!$C:$C," ")
